[2024-02-22 10:06:38,628][flwr][WARNING] - 
Setting `min_available_clients` lower than `min_fit_clients` or
`min_evaluate_clients` can cause the server to fail when there are too few clients
connected to the server. `min_available_clients` must be set to a value larger
than or equal to the values of `min_fit_clients` and `min_evaluate_clients`.

[2024-02-22 10:06:38,639][flwr][INFO] - Starting Flower simulation, config: ServerConfig(num_rounds=50, round_timeout=None)
[2024-02-22 10:06:41,354][flwr][INFO] - Flower VCE: Ray initialized with resources: {'memory': 7393214464.0, 'node:127.0.0.1': 1.0, 'node:__internal_head__': 1.0, 'object_store_memory': 2147483648.0, 'CPU': 8.0}
[2024-02-22 10:06:41,354][flwr][INFO] - Optimize your simulation with Flower VCE: https://flower.dev/docs/framework/how-to-run-simulations.html
[2024-02-22 10:06:41,354][flwr][INFO] - Flower VCE: Resources for each Virtual Client: {'num_cpus': 4, 'num_gpus': 0}
[2024-02-22 10:06:41,369][flwr][INFO] - Flower VCE: Creating VirtualClientEngineActorPool with 2 actors
[2024-02-22 10:06:41,370][flwr][INFO] - Initializing global parameters
[2024-02-22 10:06:41,370][flwr][INFO] - Using initial parameters provided by strategy
[2024-02-22 10:06:41,370][flwr][INFO] - Evaluating initial parameters
[2024-02-22 10:08:00,650][flwr][INFO] - initial parameters (loss, other metrics): 0.04605170249938965, {'accuracy': 0.1056}
[2024-02-22 10:08:00,651][flwr][INFO] - FL starting
[2024-02-22 10:08:00,651][flwr][DEBUG] - fit_round 1: strategy sampled 10 clients (out of 10)
[2024-02-22 10:08:07,487][flwr][ERROR] - Traceback (most recent call last):
  File "/Users/Slaton/myvenv/flwr/lib/python3.9/site-packages/flwr/simulation/ray_transport/ray_client_proxy.py", line 151, in _submit_job
    res, updated_context = self.actor_pool.get_client_result(self.cid, timeout)
  File "/Users/Slaton/myvenv/flwr/lib/python3.9/site-packages/flwr/simulation/ray_transport/ray_actor.py", line 425, in get_client_result
    return self._fetch_future_result(cid)
  File "/Users/Slaton/myvenv/flwr/lib/python3.9/site-packages/flwr/simulation/ray_transport/ray_actor.py", line 306, in _fetch_future_result
    res_cid, res, updated_context = ray.get(
  File "/Users/Slaton/myvenv/flwr/lib/python3.9/site-packages/ray/_private/auto_init_hook.py", line 24, in auto_init_wrapper
    return fn(*args, **kwargs)
  File "/Users/Slaton/myvenv/flwr/lib/python3.9/site-packages/ray/_private/client_mode_hook.py", line 103, in wrapper
    return func(*args, **kwargs)
  File "/Users/Slaton/myvenv/flwr/lib/python3.9/site-packages/ray/_private/worker.py", line 2524, in get
    raise value.as_instanceof_cause()
ray.exceptions.RayTaskError(ClientException): [36mray::DefaultActor.run()[39m (pid=57027, ip=127.0.0.1, actor_id=5bf67ed44f1870e964b6360401000000, repr=<flwr.simulation.ray_transport.ray_actor.DefaultActor object at 0x105d49a60>)
  File "/Users/Slaton/myvenv/flwr/lib/python3.9/site-packages/flwr/simulation/ray_transport/ray_client_proxy.py", line 207, in fit
    return maybe_call_fit(
  File "/Users/Slaton/myvenv/flwr/lib/python3.9/site-packages/flwr/client/client.py", line 234, in maybe_call_fit
    return client.fit(fit_ins)
  File "/Users/Slaton/myvenv/flwr/lib/python3.9/site-packages/flwr/client/numpy_client.py", line 238, in _fit
    results = self.numpy_client.fit(parameters, ins.config)  # type: ignore
  File "/Users/Slaton/Documents/grenoble-code/fl-flower/project3-result/client.py", line 39, in fit
    self.set_parameters(parameters)
  File "/Users/Slaton/Documents/grenoble-code/fl-flower/project3-result/client.py", line 31, in set_parameters
    self.model.load_state_dict(state_dict, strict = False)
  File "/Users/Slaton/myvenv/flwr/lib/python3.9/site-packages/torch/nn/modules/module.py", line 2139, in load_state_dict
    load(self, state_dict)
  File "/Users/Slaton/myvenv/flwr/lib/python3.9/site-packages/torch/nn/modules/module.py", line 2127, in load
    load(child, child_state_dict, child_prefix)
  File "/Users/Slaton/myvenv/flwr/lib/python3.9/site-packages/torch/nn/modules/module.py", line 2127, in load
    load(child, child_state_dict, child_prefix)
  File "/Users/Slaton/myvenv/flwr/lib/python3.9/site-packages/torch/nn/modules/module.py", line 2127, in load
    load(child, child_state_dict, child_prefix)
  File "/Users/Slaton/myvenv/flwr/lib/python3.9/site-packages/torch/nn/modules/module.py", line 2121, in load
    module._load_from_state_dict(
  File "/Users/Slaton/myvenv/flwr/lib/python3.9/site-packages/torch/nn/modules/batchnorm.py", line 114, in _load_from_state_dict
    super()._load_from_state_dict(
  File "/Users/Slaton/myvenv/flwr/lib/python3.9/site-packages/torch/nn/modules/module.py", line 2015, in _load_from_state_dict
    input_param = input_param[0]
IndexError: index 0 is out of bounds for dimension 0 with size 0

The above exception was the direct cause of the following exception:

[36mray::DefaultActor.run()[39m (pid=57027, ip=127.0.0.1, actor_id=5bf67ed44f1870e964b6360401000000, repr=<flwr.simulation.ray_transport.ray_actor.DefaultActor object at 0x105d49a60>)
  File "/Users/Slaton/myvenv/flwr/lib/python3.9/site-packages/flwr/simulation/ray_transport/ray_actor.py", line 90, in run
    raise ClientException(str(message)) from ex
flwr.simulation.ray_transport.ray_actor.ClientException: 
>>>>>>>A ClientException occurred.('\n\tSomething went wrong when running your client run.\n\tClient 3 crashed when the DefaultActor was running its run.\n\tException triggered on the client side: Traceback (most recent call last):\n  File "/Users/Slaton/myvenv/flwr/lib/python3.9/site-packages/flwr/simulation/ray_transport/ray_actor.py", line 76, in run\n    job_results = job_fn(client)\n  File "/Users/Slaton/myvenv/flwr/lib/python3.9/site-packages/flwr/simulation/ray_transport/ray_client_proxy.py", line 207, in fit\n    return maybe_call_fit(\n  File "/Users/Slaton/myvenv/flwr/lib/python3.9/site-packages/flwr/client/client.py", line 234, in maybe_call_fit\n    return client.fit(fit_ins)\n  File "/Users/Slaton/myvenv/flwr/lib/python3.9/site-packages/flwr/client/numpy_client.py", line 238, in _fit\n    results = self.numpy_client.fit(parameters, ins.config)  # type: ignore\n  File "/Users/Slaton/Documents/grenoble-code/fl-flower/project3-result/client.py", line 39, in fit\n    self.set_parameters(parameters)\n  File "/Users/Slaton/Documents/grenoble-code/fl-flower/project3-result/client.py", line 31, in set_parameters\n    self.model.load_state_dict(state_dict, strict = False)\n  File "/Users/Slaton/myvenv/flwr/lib/python3.9/site-packages/torch/nn/modules/module.py", line 2139, in load_state_dict\n    load(self, state_dict)\n  File "/Users/Slaton/myvenv/flwr/lib/python3.9/site-packages/torch/nn/modules/module.py", line 2127, in load\n    load(child, child_state_dict, child_prefix)\n  File "/Users/Slaton/myvenv/flwr/lib/python3.9/site-packages/torch/nn/modules/module.py", line 2127, in load\n    load(child, child_state_dict, child_prefix)\n  File "/Users/Slaton/myvenv/flwr/lib/python3.9/site-packages/torch/nn/modules/module.py", line 2127, in load\n    load(child, child_state_dict, child_prefix)\n  File "/Users/Slaton/myvenv/flwr/lib/python3.9/site-packages/torch/nn/modules/module.py", line 2121, in load\n    module._load_from_state_dict(\n  File "/Users/Slaton/myvenv/flwr/lib/python3.9/site-packages/torch/nn/modules/batchnorm.py", line 114, in _load_from_state_dict\n    super()._load_from_state_dict(\n  File "/Users/Slaton/myvenv/flwr/lib/python3.9/site-packages/torch/nn/modules/module.py", line 2015, in _load_from_state_dict\n    input_param = input_param[0]\nIndexError: index 0 is out of bounds for dimension 0 with size 0\n',)

[2024-02-22 10:08:07,488][flwr][ERROR] - [36mray::DefaultActor.run()[39m (pid=57027, ip=127.0.0.1, actor_id=5bf67ed44f1870e964b6360401000000, repr=<flwr.simulation.ray_transport.ray_actor.DefaultActor object at 0x105d49a60>)
  File "/Users/Slaton/myvenv/flwr/lib/python3.9/site-packages/flwr/simulation/ray_transport/ray_client_proxy.py", line 207, in fit
    return maybe_call_fit(
  File "/Users/Slaton/myvenv/flwr/lib/python3.9/site-packages/flwr/client/client.py", line 234, in maybe_call_fit
    return client.fit(fit_ins)
  File "/Users/Slaton/myvenv/flwr/lib/python3.9/site-packages/flwr/client/numpy_client.py", line 238, in _fit
    results = self.numpy_client.fit(parameters, ins.config)  # type: ignore
  File "/Users/Slaton/Documents/grenoble-code/fl-flower/project3-result/client.py", line 39, in fit
    self.set_parameters(parameters)
  File "/Users/Slaton/Documents/grenoble-code/fl-flower/project3-result/client.py", line 31, in set_parameters
    self.model.load_state_dict(state_dict, strict = False)
  File "/Users/Slaton/myvenv/flwr/lib/python3.9/site-packages/torch/nn/modules/module.py", line 2139, in load_state_dict
    load(self, state_dict)
  File "/Users/Slaton/myvenv/flwr/lib/python3.9/site-packages/torch/nn/modules/module.py", line 2127, in load
    load(child, child_state_dict, child_prefix)
  File "/Users/Slaton/myvenv/flwr/lib/python3.9/site-packages/torch/nn/modules/module.py", line 2127, in load
    load(child, child_state_dict, child_prefix)
  File "/Users/Slaton/myvenv/flwr/lib/python3.9/site-packages/torch/nn/modules/module.py", line 2127, in load
    load(child, child_state_dict, child_prefix)
  File "/Users/Slaton/myvenv/flwr/lib/python3.9/site-packages/torch/nn/modules/module.py", line 2121, in load
    module._load_from_state_dict(
  File "/Users/Slaton/myvenv/flwr/lib/python3.9/site-packages/torch/nn/modules/batchnorm.py", line 114, in _load_from_state_dict
    super()._load_from_state_dict(
  File "/Users/Slaton/myvenv/flwr/lib/python3.9/site-packages/torch/nn/modules/module.py", line 2015, in _load_from_state_dict
    input_param = input_param[0]
IndexError: index 0 is out of bounds for dimension 0 with size 0

The above exception was the direct cause of the following exception:

[36mray::DefaultActor.run()[39m (pid=57027, ip=127.0.0.1, actor_id=5bf67ed44f1870e964b6360401000000, repr=<flwr.simulation.ray_transport.ray_actor.DefaultActor object at 0x105d49a60>)
  File "/Users/Slaton/myvenv/flwr/lib/python3.9/site-packages/flwr/simulation/ray_transport/ray_actor.py", line 90, in run
    raise ClientException(str(message)) from ex
flwr.simulation.ray_transport.ray_actor.ClientException: 
>>>>>>>A ClientException occurred.('\n\tSomething went wrong when running your client run.\n\tClient 3 crashed when the DefaultActor was running its run.\n\tException triggered on the client side: Traceback (most recent call last):\n  File "/Users/Slaton/myvenv/flwr/lib/python3.9/site-packages/flwr/simulation/ray_transport/ray_actor.py", line 76, in run\n    job_results = job_fn(client)\n  File "/Users/Slaton/myvenv/flwr/lib/python3.9/site-packages/flwr/simulation/ray_transport/ray_client_proxy.py", line 207, in fit\n    return maybe_call_fit(\n  File "/Users/Slaton/myvenv/flwr/lib/python3.9/site-packages/flwr/client/client.py", line 234, in maybe_call_fit\n    return client.fit(fit_ins)\n  File "/Users/Slaton/myvenv/flwr/lib/python3.9/site-packages/flwr/client/numpy_client.py", line 238, in _fit\n    results = self.numpy_client.fit(parameters, ins.config)  # type: ignore\n  File "/Users/Slaton/Documents/grenoble-code/fl-flower/project3-result/client.py", line 39, in fit\n    self.set_parameters(parameters)\n  File "/Users/Slaton/Documents/grenoble-code/fl-flower/project3-result/client.py", line 31, in set_parameters\n    self.model.load_state_dict(state_dict, strict = False)\n  File "/Users/Slaton/myvenv/flwr/lib/python3.9/site-packages/torch/nn/modules/module.py", line 2139, in load_state_dict\n    load(self, state_dict)\n  File "/Users/Slaton/myvenv/flwr/lib/python3.9/site-packages/torch/nn/modules/module.py", line 2127, in load\n    load(child, child_state_dict, child_prefix)\n  File "/Users/Slaton/myvenv/flwr/lib/python3.9/site-packages/torch/nn/modules/module.py", line 2127, in load\n    load(child, child_state_dict, child_prefix)\n  File "/Users/Slaton/myvenv/flwr/lib/python3.9/site-packages/torch/nn/modules/module.py", line 2127, in load\n    load(child, child_state_dict, child_prefix)\n  File "/Users/Slaton/myvenv/flwr/lib/python3.9/site-packages/torch/nn/modules/module.py", line 2121, in load\n    module._load_from_state_dict(\n  File "/Users/Slaton/myvenv/flwr/lib/python3.9/site-packages/torch/nn/modules/batchnorm.py", line 114, in _load_from_state_dict\n    super()._load_from_state_dict(\n  File "/Users/Slaton/myvenv/flwr/lib/python3.9/site-packages/torch/nn/modules/module.py", line 2015, in _load_from_state_dict\n    input_param = input_param[0]\nIndexError: index 0 is out of bounds for dimension 0 with size 0\n',)
[2024-02-22 10:08:07,537][flwr][ERROR] - Traceback (most recent call last):
  File "/Users/Slaton/myvenv/flwr/lib/python3.9/site-packages/flwr/simulation/ray_transport/ray_client_proxy.py", line 151, in _submit_job
    res, updated_context = self.actor_pool.get_client_result(self.cid, timeout)
  File "/Users/Slaton/myvenv/flwr/lib/python3.9/site-packages/flwr/simulation/ray_transport/ray_actor.py", line 425, in get_client_result
    return self._fetch_future_result(cid)
  File "/Users/Slaton/myvenv/flwr/lib/python3.9/site-packages/flwr/simulation/ray_transport/ray_actor.py", line 306, in _fetch_future_result
    res_cid, res, updated_context = ray.get(
  File "/Users/Slaton/myvenv/flwr/lib/python3.9/site-packages/ray/_private/auto_init_hook.py", line 24, in auto_init_wrapper
    return fn(*args, **kwargs)
  File "/Users/Slaton/myvenv/flwr/lib/python3.9/site-packages/ray/_private/client_mode_hook.py", line 103, in wrapper
    return func(*args, **kwargs)
  File "/Users/Slaton/myvenv/flwr/lib/python3.9/site-packages/ray/_private/worker.py", line 2524, in get
    raise value.as_instanceof_cause()
ray.exceptions.RayTaskError(ClientException): [36mray::DefaultActor.run()[39m (pid=57028, ip=127.0.0.1, actor_id=4c7ac826f305fef553fc9eee01000000, repr=<flwr.simulation.ray_transport.ray_actor.DefaultActor object at 0x111511a00>)
  File "/Users/Slaton/myvenv/flwr/lib/python3.9/site-packages/flwr/simulation/ray_transport/ray_client_proxy.py", line 207, in fit
    return maybe_call_fit(
  File "/Users/Slaton/myvenv/flwr/lib/python3.9/site-packages/flwr/client/client.py", line 234, in maybe_call_fit
    return client.fit(fit_ins)
  File "/Users/Slaton/myvenv/flwr/lib/python3.9/site-packages/flwr/client/numpy_client.py", line 238, in _fit
    results = self.numpy_client.fit(parameters, ins.config)  # type: ignore
  File "/Users/Slaton/Documents/grenoble-code/fl-flower/project3-result/client.py", line 39, in fit
    self.set_parameters(parameters)
  File "/Users/Slaton/Documents/grenoble-code/fl-flower/project3-result/client.py", line 31, in set_parameters
    self.model.load_state_dict(state_dict, strict = False)
  File "/Users/Slaton/myvenv/flwr/lib/python3.9/site-packages/torch/nn/modules/module.py", line 2139, in load_state_dict
    load(self, state_dict)
  File "/Users/Slaton/myvenv/flwr/lib/python3.9/site-packages/torch/nn/modules/module.py", line 2127, in load
    load(child, child_state_dict, child_prefix)
  File "/Users/Slaton/myvenv/flwr/lib/python3.9/site-packages/torch/nn/modules/module.py", line 2127, in load
    load(child, child_state_dict, child_prefix)
  File "/Users/Slaton/myvenv/flwr/lib/python3.9/site-packages/torch/nn/modules/module.py", line 2127, in load
    load(child, child_state_dict, child_prefix)
  File "/Users/Slaton/myvenv/flwr/lib/python3.9/site-packages/torch/nn/modules/module.py", line 2121, in load
    module._load_from_state_dict(
  File "/Users/Slaton/myvenv/flwr/lib/python3.9/site-packages/torch/nn/modules/batchnorm.py", line 114, in _load_from_state_dict
    super()._load_from_state_dict(
  File "/Users/Slaton/myvenv/flwr/lib/python3.9/site-packages/torch/nn/modules/module.py", line 2015, in _load_from_state_dict
    input_param = input_param[0]
IndexError: index 0 is out of bounds for dimension 0 with size 0

The above exception was the direct cause of the following exception:

[36mray::DefaultActor.run()[39m (pid=57028, ip=127.0.0.1, actor_id=4c7ac826f305fef553fc9eee01000000, repr=<flwr.simulation.ray_transport.ray_actor.DefaultActor object at 0x111511a00>)
  File "/Users/Slaton/myvenv/flwr/lib/python3.9/site-packages/flwr/simulation/ray_transport/ray_actor.py", line 90, in run
    raise ClientException(str(message)) from ex
flwr.simulation.ray_transport.ray_actor.ClientException: 
>>>>>>>A ClientException occurred.('\n\tSomething went wrong when running your client run.\n\tClient 2 crashed when the DefaultActor was running its run.\n\tException triggered on the client side: Traceback (most recent call last):\n  File "/Users/Slaton/myvenv/flwr/lib/python3.9/site-packages/flwr/simulation/ray_transport/ray_actor.py", line 76, in run\n    job_results = job_fn(client)\n  File "/Users/Slaton/myvenv/flwr/lib/python3.9/site-packages/flwr/simulation/ray_transport/ray_client_proxy.py", line 207, in fit\n    return maybe_call_fit(\n  File "/Users/Slaton/myvenv/flwr/lib/python3.9/site-packages/flwr/client/client.py", line 234, in maybe_call_fit\n    return client.fit(fit_ins)\n  File "/Users/Slaton/myvenv/flwr/lib/python3.9/site-packages/flwr/client/numpy_client.py", line 238, in _fit\n    results = self.numpy_client.fit(parameters, ins.config)  # type: ignore\n  File "/Users/Slaton/Documents/grenoble-code/fl-flower/project3-result/client.py", line 39, in fit\n    self.set_parameters(parameters)\n  File "/Users/Slaton/Documents/grenoble-code/fl-flower/project3-result/client.py", line 31, in set_parameters\n    self.model.load_state_dict(state_dict, strict = False)\n  File "/Users/Slaton/myvenv/flwr/lib/python3.9/site-packages/torch/nn/modules/module.py", line 2139, in load_state_dict\n    load(self, state_dict)\n  File "/Users/Slaton/myvenv/flwr/lib/python3.9/site-packages/torch/nn/modules/module.py", line 2127, in load\n    load(child, child_state_dict, child_prefix)\n  File "/Users/Slaton/myvenv/flwr/lib/python3.9/site-packages/torch/nn/modules/module.py", line 2127, in load\n    load(child, child_state_dict, child_prefix)\n  File "/Users/Slaton/myvenv/flwr/lib/python3.9/site-packages/torch/nn/modules/module.py", line 2127, in load\n    load(child, child_state_dict, child_prefix)\n  File "/Users/Slaton/myvenv/flwr/lib/python3.9/site-packages/torch/nn/modules/module.py", line 2121, in load\n    module._load_from_state_dict(\n  File "/Users/Slaton/myvenv/flwr/lib/python3.9/site-packages/torch/nn/modules/batchnorm.py", line 114, in _load_from_state_dict\n    super()._load_from_state_dict(\n  File "/Users/Slaton/myvenv/flwr/lib/python3.9/site-packages/torch/nn/modules/module.py", line 2015, in _load_from_state_dict\n    input_param = input_param[0]\nIndexError: index 0 is out of bounds for dimension 0 with size 0\n',)

[2024-02-22 10:08:07,538][flwr][ERROR] - Traceback (most recent call last):
  File "/Users/Slaton/myvenv/flwr/lib/python3.9/site-packages/flwr/simulation/ray_transport/ray_client_proxy.py", line 151, in _submit_job
    res, updated_context = self.actor_pool.get_client_result(self.cid, timeout)
  File "/Users/Slaton/myvenv/flwr/lib/python3.9/site-packages/flwr/simulation/ray_transport/ray_actor.py", line 425, in get_client_result
    return self._fetch_future_result(cid)
  File "/Users/Slaton/myvenv/flwr/lib/python3.9/site-packages/flwr/simulation/ray_transport/ray_actor.py", line 306, in _fetch_future_result
    res_cid, res, updated_context = ray.get(
  File "/Users/Slaton/myvenv/flwr/lib/python3.9/site-packages/ray/_private/auto_init_hook.py", line 24, in auto_init_wrapper
    return fn(*args, **kwargs)
  File "/Users/Slaton/myvenv/flwr/lib/python3.9/site-packages/ray/_private/client_mode_hook.py", line 103, in wrapper
    return func(*args, **kwargs)
  File "/Users/Slaton/myvenv/flwr/lib/python3.9/site-packages/ray/_private/worker.py", line 2524, in get
    raise value.as_instanceof_cause()
ray.exceptions.RayTaskError(ClientException): [36mray::DefaultActor.run()[39m (pid=57028, ip=127.0.0.1, actor_id=4c7ac826f305fef553fc9eee01000000, repr=<flwr.simulation.ray_transport.ray_actor.DefaultActor object at 0x111511a00>)
  File "/Users/Slaton/myvenv/flwr/lib/python3.9/site-packages/flwr/simulation/ray_transport/ray_client_proxy.py", line 207, in fit
    return maybe_call_fit(
  File "/Users/Slaton/myvenv/flwr/lib/python3.9/site-packages/flwr/client/client.py", line 234, in maybe_call_fit
    return client.fit(fit_ins)
  File "/Users/Slaton/myvenv/flwr/lib/python3.9/site-packages/flwr/client/numpy_client.py", line 238, in _fit
    results = self.numpy_client.fit(parameters, ins.config)  # type: ignore
  File "/Users/Slaton/Documents/grenoble-code/fl-flower/project3-result/client.py", line 39, in fit
    self.set_parameters(parameters)
  File "/Users/Slaton/Documents/grenoble-code/fl-flower/project3-result/client.py", line 31, in set_parameters
    self.model.load_state_dict(state_dict, strict = False)
  File "/Users/Slaton/myvenv/flwr/lib/python3.9/site-packages/torch/nn/modules/module.py", line 2139, in load_state_dict
    load(self, state_dict)
  File "/Users/Slaton/myvenv/flwr/lib/python3.9/site-packages/torch/nn/modules/module.py", line 2127, in load
    load(child, child_state_dict, child_prefix)
  File "/Users/Slaton/myvenv/flwr/lib/python3.9/site-packages/torch/nn/modules/module.py", line 2127, in load
    load(child, child_state_dict, child_prefix)
  File "/Users/Slaton/myvenv/flwr/lib/python3.9/site-packages/torch/nn/modules/module.py", line 2127, in load
    load(child, child_state_dict, child_prefix)
  File "/Users/Slaton/myvenv/flwr/lib/python3.9/site-packages/torch/nn/modules/module.py", line 2121, in load
    module._load_from_state_dict(
  File "/Users/Slaton/myvenv/flwr/lib/python3.9/site-packages/torch/nn/modules/batchnorm.py", line 114, in _load_from_state_dict
    super()._load_from_state_dict(
  File "/Users/Slaton/myvenv/flwr/lib/python3.9/site-packages/torch/nn/modules/module.py", line 2015, in _load_from_state_dict
    input_param = input_param[0]
IndexError: index 0 is out of bounds for dimension 0 with size 0

The above exception was the direct cause of the following exception:

[36mray::DefaultActor.run()[39m (pid=57028, ip=127.0.0.1, actor_id=4c7ac826f305fef553fc9eee01000000, repr=<flwr.simulation.ray_transport.ray_actor.DefaultActor object at 0x111511a00>)
  File "/Users/Slaton/myvenv/flwr/lib/python3.9/site-packages/flwr/simulation/ray_transport/ray_actor.py", line 90, in run
    raise ClientException(str(message)) from ex
flwr.simulation.ray_transport.ray_actor.ClientException: 
>>>>>>>A ClientException occurred.('\n\tSomething went wrong when running your client run.\n\tClient 7 crashed when the DefaultActor was running its run.\n\tException triggered on the client side: Traceback (most recent call last):\n  File "/Users/Slaton/myvenv/flwr/lib/python3.9/site-packages/flwr/simulation/ray_transport/ray_actor.py", line 76, in run\n    job_results = job_fn(client)\n  File "/Users/Slaton/myvenv/flwr/lib/python3.9/site-packages/flwr/simulation/ray_transport/ray_client_proxy.py", line 207, in fit\n    return maybe_call_fit(\n  File "/Users/Slaton/myvenv/flwr/lib/python3.9/site-packages/flwr/client/client.py", line 234, in maybe_call_fit\n    return client.fit(fit_ins)\n  File "/Users/Slaton/myvenv/flwr/lib/python3.9/site-packages/flwr/client/numpy_client.py", line 238, in _fit\n    results = self.numpy_client.fit(parameters, ins.config)  # type: ignore\n  File "/Users/Slaton/Documents/grenoble-code/fl-flower/project3-result/client.py", line 39, in fit\n    self.set_parameters(parameters)\n  File "/Users/Slaton/Documents/grenoble-code/fl-flower/project3-result/client.py", line 31, in set_parameters\n    self.model.load_state_dict(state_dict, strict = False)\n  File "/Users/Slaton/myvenv/flwr/lib/python3.9/site-packages/torch/nn/modules/module.py", line 2139, in load_state_dict\n    load(self, state_dict)\n  File "/Users/Slaton/myvenv/flwr/lib/python3.9/site-packages/torch/nn/modules/module.py", line 2127, in load\n    load(child, child_state_dict, child_prefix)\n  File "/Users/Slaton/myvenv/flwr/lib/python3.9/site-packages/torch/nn/modules/module.py", line 2127, in load\n    load(child, child_state_dict, child_prefix)\n  File "/Users/Slaton/myvenv/flwr/lib/python3.9/site-packages/torch/nn/modules/module.py", line 2127, in load\n    load(child, child_state_dict, child_prefix)\n  File "/Users/Slaton/myvenv/flwr/lib/python3.9/site-packages/torch/nn/modules/module.py", line 2121, in load\n    module._load_from_state_dict(\n  File "/Users/Slaton/myvenv/flwr/lib/python3.9/site-packages/torch/nn/modules/batchnorm.py", line 114, in _load_from_state_dict\n    super()._load_from_state_dict(\n  File "/Users/Slaton/myvenv/flwr/lib/python3.9/site-packages/torch/nn/modules/module.py", line 2015, in _load_from_state_dict\n    input_param = input_param[0]\nIndexError: index 0 is out of bounds for dimension 0 with size 0\n',)

[2024-02-22 10:08:07,538][flwr][ERROR] - [36mray::DefaultActor.run()[39m (pid=57028, ip=127.0.0.1, actor_id=4c7ac826f305fef553fc9eee01000000, repr=<flwr.simulation.ray_transport.ray_actor.DefaultActor object at 0x111511a00>)
  File "/Users/Slaton/myvenv/flwr/lib/python3.9/site-packages/flwr/simulation/ray_transport/ray_client_proxy.py", line 207, in fit
    return maybe_call_fit(
  File "/Users/Slaton/myvenv/flwr/lib/python3.9/site-packages/flwr/client/client.py", line 234, in maybe_call_fit
    return client.fit(fit_ins)
  File "/Users/Slaton/myvenv/flwr/lib/python3.9/site-packages/flwr/client/numpy_client.py", line 238, in _fit
    results = self.numpy_client.fit(parameters, ins.config)  # type: ignore
  File "/Users/Slaton/Documents/grenoble-code/fl-flower/project3-result/client.py", line 39, in fit
    self.set_parameters(parameters)
  File "/Users/Slaton/Documents/grenoble-code/fl-flower/project3-result/client.py", line 31, in set_parameters
    self.model.load_state_dict(state_dict, strict = False)
  File "/Users/Slaton/myvenv/flwr/lib/python3.9/site-packages/torch/nn/modules/module.py", line 2139, in load_state_dict
    load(self, state_dict)
  File "/Users/Slaton/myvenv/flwr/lib/python3.9/site-packages/torch/nn/modules/module.py", line 2127, in load
    load(child, child_state_dict, child_prefix)
  File "/Users/Slaton/myvenv/flwr/lib/python3.9/site-packages/torch/nn/modules/module.py", line 2127, in load
    load(child, child_state_dict, child_prefix)
  File "/Users/Slaton/myvenv/flwr/lib/python3.9/site-packages/torch/nn/modules/module.py", line 2127, in load
    load(child, child_state_dict, child_prefix)
  File "/Users/Slaton/myvenv/flwr/lib/python3.9/site-packages/torch/nn/modules/module.py", line 2121, in load
    module._load_from_state_dict(
  File "/Users/Slaton/myvenv/flwr/lib/python3.9/site-packages/torch/nn/modules/batchnorm.py", line 114, in _load_from_state_dict
    super()._load_from_state_dict(
  File "/Users/Slaton/myvenv/flwr/lib/python3.9/site-packages/torch/nn/modules/module.py", line 2015, in _load_from_state_dict
    input_param = input_param[0]
IndexError: index 0 is out of bounds for dimension 0 with size 0

The above exception was the direct cause of the following exception:

[36mray::DefaultActor.run()[39m (pid=57028, ip=127.0.0.1, actor_id=4c7ac826f305fef553fc9eee01000000, repr=<flwr.simulation.ray_transport.ray_actor.DefaultActor object at 0x111511a00>)
  File "/Users/Slaton/myvenv/flwr/lib/python3.9/site-packages/flwr/simulation/ray_transport/ray_actor.py", line 90, in run
    raise ClientException(str(message)) from ex
flwr.simulation.ray_transport.ray_actor.ClientException: 
>>>>>>>A ClientException occurred.('\n\tSomething went wrong when running your client run.\n\tClient 2 crashed when the DefaultActor was running its run.\n\tException triggered on the client side: Traceback (most recent call last):\n  File "/Users/Slaton/myvenv/flwr/lib/python3.9/site-packages/flwr/simulation/ray_transport/ray_actor.py", line 76, in run\n    job_results = job_fn(client)\n  File "/Users/Slaton/myvenv/flwr/lib/python3.9/site-packages/flwr/simulation/ray_transport/ray_client_proxy.py", line 207, in fit\n    return maybe_call_fit(\n  File "/Users/Slaton/myvenv/flwr/lib/python3.9/site-packages/flwr/client/client.py", line 234, in maybe_call_fit\n    return client.fit(fit_ins)\n  File "/Users/Slaton/myvenv/flwr/lib/python3.9/site-packages/flwr/client/numpy_client.py", line 238, in _fit\n    results = self.numpy_client.fit(parameters, ins.config)  # type: ignore\n  File "/Users/Slaton/Documents/grenoble-code/fl-flower/project3-result/client.py", line 39, in fit\n    self.set_parameters(parameters)\n  File "/Users/Slaton/Documents/grenoble-code/fl-flower/project3-result/client.py", line 31, in set_parameters\n    self.model.load_state_dict(state_dict, strict = False)\n  File "/Users/Slaton/myvenv/flwr/lib/python3.9/site-packages/torch/nn/modules/module.py", line 2139, in load_state_dict\n    load(self, state_dict)\n  File "/Users/Slaton/myvenv/flwr/lib/python3.9/site-packages/torch/nn/modules/module.py", line 2127, in load\n    load(child, child_state_dict, child_prefix)\n  File "/Users/Slaton/myvenv/flwr/lib/python3.9/site-packages/torch/nn/modules/module.py", line 2127, in load\n    load(child, child_state_dict, child_prefix)\n  File "/Users/Slaton/myvenv/flwr/lib/python3.9/site-packages/torch/nn/modules/module.py", line 2127, in load\n    load(child, child_state_dict, child_prefix)\n  File "/Users/Slaton/myvenv/flwr/lib/python3.9/site-packages/torch/nn/modules/module.py", line 2121, in load\n    module._load_from_state_dict(\n  File "/Users/Slaton/myvenv/flwr/lib/python3.9/site-packages/torch/nn/modules/batchnorm.py", line 114, in _load_from_state_dict\n    super()._load_from_state_dict(\n  File "/Users/Slaton/myvenv/flwr/lib/python3.9/site-packages/torch/nn/modules/module.py", line 2015, in _load_from_state_dict\n    input_param = input_param[0]\nIndexError: index 0 is out of bounds for dimension 0 with size 0\n',)
[2024-02-22 10:08:08,622][flwr][ERROR] - [36mray::DefaultActor.run()[39m (pid=57028, ip=127.0.0.1, actor_id=4c7ac826f305fef553fc9eee01000000, repr=<flwr.simulation.ray_transport.ray_actor.DefaultActor object at 0x111511a00>)
  File "/Users/Slaton/myvenv/flwr/lib/python3.9/site-packages/flwr/simulation/ray_transport/ray_client_proxy.py", line 207, in fit
    return maybe_call_fit(
  File "/Users/Slaton/myvenv/flwr/lib/python3.9/site-packages/flwr/client/client.py", line 234, in maybe_call_fit
    return client.fit(fit_ins)
  File "/Users/Slaton/myvenv/flwr/lib/python3.9/site-packages/flwr/client/numpy_client.py", line 238, in _fit
    results = self.numpy_client.fit(parameters, ins.config)  # type: ignore
  File "/Users/Slaton/Documents/grenoble-code/fl-flower/project3-result/client.py", line 39, in fit
    self.set_parameters(parameters)
  File "/Users/Slaton/Documents/grenoble-code/fl-flower/project3-result/client.py", line 31, in set_parameters
    self.model.load_state_dict(state_dict, strict = False)
  File "/Users/Slaton/myvenv/flwr/lib/python3.9/site-packages/torch/nn/modules/module.py", line 2139, in load_state_dict
    load(self, state_dict)
  File "/Users/Slaton/myvenv/flwr/lib/python3.9/site-packages/torch/nn/modules/module.py", line 2127, in load
    load(child, child_state_dict, child_prefix)
  File "/Users/Slaton/myvenv/flwr/lib/python3.9/site-packages/torch/nn/modules/module.py", line 2127, in load
    load(child, child_state_dict, child_prefix)
  File "/Users/Slaton/myvenv/flwr/lib/python3.9/site-packages/torch/nn/modules/module.py", line 2127, in load
    load(child, child_state_dict, child_prefix)
  File "/Users/Slaton/myvenv/flwr/lib/python3.9/site-packages/torch/nn/modules/module.py", line 2121, in load
    module._load_from_state_dict(
  File "/Users/Slaton/myvenv/flwr/lib/python3.9/site-packages/torch/nn/modules/batchnorm.py", line 114, in _load_from_state_dict
    super()._load_from_state_dict(
  File "/Users/Slaton/myvenv/flwr/lib/python3.9/site-packages/torch/nn/modules/module.py", line 2015, in _load_from_state_dict
    input_param = input_param[0]
IndexError: index 0 is out of bounds for dimension 0 with size 0

The above exception was the direct cause of the following exception:

[36mray::DefaultActor.run()[39m (pid=57028, ip=127.0.0.1, actor_id=4c7ac826f305fef553fc9eee01000000, repr=<flwr.simulation.ray_transport.ray_actor.DefaultActor object at 0x111511a00>)
  File "/Users/Slaton/myvenv/flwr/lib/python3.9/site-packages/flwr/simulation/ray_transport/ray_actor.py", line 90, in run
    raise ClientException(str(message)) from ex
flwr.simulation.ray_transport.ray_actor.ClientException: 
>>>>>>>A ClientException occurred.('\n\tSomething went wrong when running your client run.\n\tClient 7 crashed when the DefaultActor was running its run.\n\tException triggered on the client side: Traceback (most recent call last):\n  File "/Users/Slaton/myvenv/flwr/lib/python3.9/site-packages/flwr/simulation/ray_transport/ray_actor.py", line 76, in run\n    job_results = job_fn(client)\n  File "/Users/Slaton/myvenv/flwr/lib/python3.9/site-packages/flwr/simulation/ray_transport/ray_client_proxy.py", line 207, in fit\n    return maybe_call_fit(\n  File "/Users/Slaton/myvenv/flwr/lib/python3.9/site-packages/flwr/client/client.py", line 234, in maybe_call_fit\n    return client.fit(fit_ins)\n  File "/Users/Slaton/myvenv/flwr/lib/python3.9/site-packages/flwr/client/numpy_client.py", line 238, in _fit\n    results = self.numpy_client.fit(parameters, ins.config)  # type: ignore\n  File "/Users/Slaton/Documents/grenoble-code/fl-flower/project3-result/client.py", line 39, in fit\n    self.set_parameters(parameters)\n  File "/Users/Slaton/Documents/grenoble-code/fl-flower/project3-result/client.py", line 31, in set_parameters\n    self.model.load_state_dict(state_dict, strict = False)\n  File "/Users/Slaton/myvenv/flwr/lib/python3.9/site-packages/torch/nn/modules/module.py", line 2139, in load_state_dict\n    load(self, state_dict)\n  File "/Users/Slaton/myvenv/flwr/lib/python3.9/site-packages/torch/nn/modules/module.py", line 2127, in load\n    load(child, child_state_dict, child_prefix)\n  File "/Users/Slaton/myvenv/flwr/lib/python3.9/site-packages/torch/nn/modules/module.py", line 2127, in load\n    load(child, child_state_dict, child_prefix)\n  File "/Users/Slaton/myvenv/flwr/lib/python3.9/site-packages/torch/nn/modules/module.py", line 2127, in load\n    load(child, child_state_dict, child_prefix)\n  File "/Users/Slaton/myvenv/flwr/lib/python3.9/site-packages/torch/nn/modules/module.py", line 2121, in load\n    module._load_from_state_dict(\n  File "/Users/Slaton/myvenv/flwr/lib/python3.9/site-packages/torch/nn/modules/batchnorm.py", line 114, in _load_from_state_dict\n    super()._load_from_state_dict(\n  File "/Users/Slaton/myvenv/flwr/lib/python3.9/site-packages/torch/nn/modules/module.py", line 2015, in _load_from_state_dict\n    input_param = input_param[0]\nIndexError: index 0 is out of bounds for dimension 0 with size 0\n',)
[2024-02-22 10:08:09,699][flwr][ERROR] - Traceback (most recent call last):
  File "/Users/Slaton/myvenv/flwr/lib/python3.9/site-packages/flwr/simulation/ray_transport/ray_client_proxy.py", line 151, in _submit_job
    res, updated_context = self.actor_pool.get_client_result(self.cid, timeout)
  File "/Users/Slaton/myvenv/flwr/lib/python3.9/site-packages/flwr/simulation/ray_transport/ray_actor.py", line 425, in get_client_result
    return self._fetch_future_result(cid)
  File "/Users/Slaton/myvenv/flwr/lib/python3.9/site-packages/flwr/simulation/ray_transport/ray_actor.py", line 306, in _fetch_future_result
    res_cid, res, updated_context = ray.get(
  File "/Users/Slaton/myvenv/flwr/lib/python3.9/site-packages/ray/_private/auto_init_hook.py", line 24, in auto_init_wrapper
    return fn(*args, **kwargs)
  File "/Users/Slaton/myvenv/flwr/lib/python3.9/site-packages/ray/_private/client_mode_hook.py", line 103, in wrapper
    return func(*args, **kwargs)
  File "/Users/Slaton/myvenv/flwr/lib/python3.9/site-packages/ray/_private/worker.py", line 2524, in get
    raise value.as_instanceof_cause()
ray.exceptions.RayTaskError(ClientException): [36mray::DefaultActor.run()[39m (pid=57027, ip=127.0.0.1, actor_id=5bf67ed44f1870e964b6360401000000, repr=<flwr.simulation.ray_transport.ray_actor.DefaultActor object at 0x105d49a60>)
  File "/Users/Slaton/myvenv/flwr/lib/python3.9/site-packages/flwr/simulation/ray_transport/ray_client_proxy.py", line 207, in fit
    return maybe_call_fit(
  File "/Users/Slaton/myvenv/flwr/lib/python3.9/site-packages/flwr/client/client.py", line 234, in maybe_call_fit
    return client.fit(fit_ins)
  File "/Users/Slaton/myvenv/flwr/lib/python3.9/site-packages/flwr/client/numpy_client.py", line 238, in _fit
    results = self.numpy_client.fit(parameters, ins.config)  # type: ignore
  File "/Users/Slaton/Documents/grenoble-code/fl-flower/project3-result/client.py", line 39, in fit
    self.set_parameters(parameters)
  File "/Users/Slaton/Documents/grenoble-code/fl-flower/project3-result/client.py", line 31, in set_parameters
    self.model.load_state_dict(state_dict, strict = False)
  File "/Users/Slaton/myvenv/flwr/lib/python3.9/site-packages/torch/nn/modules/module.py", line 2139, in load_state_dict
    load(self, state_dict)
  File "/Users/Slaton/myvenv/flwr/lib/python3.9/site-packages/torch/nn/modules/module.py", line 2127, in load
    load(child, child_state_dict, child_prefix)
  File "/Users/Slaton/myvenv/flwr/lib/python3.9/site-packages/torch/nn/modules/module.py", line 2127, in load
    load(child, child_state_dict, child_prefix)
  File "/Users/Slaton/myvenv/flwr/lib/python3.9/site-packages/torch/nn/modules/module.py", line 2127, in load
    load(child, child_state_dict, child_prefix)
  File "/Users/Slaton/myvenv/flwr/lib/python3.9/site-packages/torch/nn/modules/module.py", line 2121, in load
    module._load_from_state_dict(
  File "/Users/Slaton/myvenv/flwr/lib/python3.9/site-packages/torch/nn/modules/batchnorm.py", line 114, in _load_from_state_dict
    super()._load_from_state_dict(
  File "/Users/Slaton/myvenv/flwr/lib/python3.9/site-packages/torch/nn/modules/module.py", line 2015, in _load_from_state_dict
    input_param = input_param[0]
IndexError: index 0 is out of bounds for dimension 0 with size 0

The above exception was the direct cause of the following exception:

[36mray::DefaultActor.run()[39m (pid=57027, ip=127.0.0.1, actor_id=5bf67ed44f1870e964b6360401000000, repr=<flwr.simulation.ray_transport.ray_actor.DefaultActor object at 0x105d49a60>)
  File "/Users/Slaton/myvenv/flwr/lib/python3.9/site-packages/flwr/simulation/ray_transport/ray_actor.py", line 90, in run
    raise ClientException(str(message)) from ex
flwr.simulation.ray_transport.ray_actor.ClientException: 
>>>>>>>A ClientException occurred.('\n\tSomething went wrong when running your client run.\n\tClient 5 crashed when the DefaultActor was running its run.\n\tException triggered on the client side: Traceback (most recent call last):\n  File "/Users/Slaton/myvenv/flwr/lib/python3.9/site-packages/flwr/simulation/ray_transport/ray_actor.py", line 76, in run\n    job_results = job_fn(client)\n  File "/Users/Slaton/myvenv/flwr/lib/python3.9/site-packages/flwr/simulation/ray_transport/ray_client_proxy.py", line 207, in fit\n    return maybe_call_fit(\n  File "/Users/Slaton/myvenv/flwr/lib/python3.9/site-packages/flwr/client/client.py", line 234, in maybe_call_fit\n    return client.fit(fit_ins)\n  File "/Users/Slaton/myvenv/flwr/lib/python3.9/site-packages/flwr/client/numpy_client.py", line 238, in _fit\n    results = self.numpy_client.fit(parameters, ins.config)  # type: ignore\n  File "/Users/Slaton/Documents/grenoble-code/fl-flower/project3-result/client.py", line 39, in fit\n    self.set_parameters(parameters)\n  File "/Users/Slaton/Documents/grenoble-code/fl-flower/project3-result/client.py", line 31, in set_parameters\n    self.model.load_state_dict(state_dict, strict = False)\n  File "/Users/Slaton/myvenv/flwr/lib/python3.9/site-packages/torch/nn/modules/module.py", line 2139, in load_state_dict\n    load(self, state_dict)\n  File "/Users/Slaton/myvenv/flwr/lib/python3.9/site-packages/torch/nn/modules/module.py", line 2127, in load\n    load(child, child_state_dict, child_prefix)\n  File "/Users/Slaton/myvenv/flwr/lib/python3.9/site-packages/torch/nn/modules/module.py", line 2127, in load\n    load(child, child_state_dict, child_prefix)\n  File "/Users/Slaton/myvenv/flwr/lib/python3.9/site-packages/torch/nn/modules/module.py", line 2127, in load\n    load(child, child_state_dict, child_prefix)\n  File "/Users/Slaton/myvenv/flwr/lib/python3.9/site-packages/torch/nn/modules/module.py", line 2121, in load\n    module._load_from_state_dict(\n  File "/Users/Slaton/myvenv/flwr/lib/python3.9/site-packages/torch/nn/modules/batchnorm.py", line 114, in _load_from_state_dict\n    super()._load_from_state_dict(\n  File "/Users/Slaton/myvenv/flwr/lib/python3.9/site-packages/torch/nn/modules/module.py", line 2015, in _load_from_state_dict\n    input_param = input_param[0]\nIndexError: index 0 is out of bounds for dimension 0 with size 0\n',)

[2024-02-22 10:08:10,955][flwr][ERROR] - [36mray::DefaultActor.run()[39m (pid=57027, ip=127.0.0.1, actor_id=5bf67ed44f1870e964b6360401000000, repr=<flwr.simulation.ray_transport.ray_actor.DefaultActor object at 0x105d49a60>)
  File "/Users/Slaton/myvenv/flwr/lib/python3.9/site-packages/flwr/simulation/ray_transport/ray_client_proxy.py", line 207, in fit
    return maybe_call_fit(
  File "/Users/Slaton/myvenv/flwr/lib/python3.9/site-packages/flwr/client/client.py", line 234, in maybe_call_fit
    return client.fit(fit_ins)
  File "/Users/Slaton/myvenv/flwr/lib/python3.9/site-packages/flwr/client/numpy_client.py", line 238, in _fit
    results = self.numpy_client.fit(parameters, ins.config)  # type: ignore
  File "/Users/Slaton/Documents/grenoble-code/fl-flower/project3-result/client.py", line 39, in fit
    self.set_parameters(parameters)
  File "/Users/Slaton/Documents/grenoble-code/fl-flower/project3-result/client.py", line 31, in set_parameters
    self.model.load_state_dict(state_dict, strict = False)
  File "/Users/Slaton/myvenv/flwr/lib/python3.9/site-packages/torch/nn/modules/module.py", line 2139, in load_state_dict
    load(self, state_dict)
  File "/Users/Slaton/myvenv/flwr/lib/python3.9/site-packages/torch/nn/modules/module.py", line 2127, in load
    load(child, child_state_dict, child_prefix)
  File "/Users/Slaton/myvenv/flwr/lib/python3.9/site-packages/torch/nn/modules/module.py", line 2127, in load
    load(child, child_state_dict, child_prefix)
  File "/Users/Slaton/myvenv/flwr/lib/python3.9/site-packages/torch/nn/modules/module.py", line 2127, in load
    load(child, child_state_dict, child_prefix)
  File "/Users/Slaton/myvenv/flwr/lib/python3.9/site-packages/torch/nn/modules/module.py", line 2121, in load
    module._load_from_state_dict(
  File "/Users/Slaton/myvenv/flwr/lib/python3.9/site-packages/torch/nn/modules/batchnorm.py", line 114, in _load_from_state_dict
    super()._load_from_state_dict(
  File "/Users/Slaton/myvenv/flwr/lib/python3.9/site-packages/torch/nn/modules/module.py", line 2015, in _load_from_state_dict
    input_param = input_param[0]
IndexError: index 0 is out of bounds for dimension 0 with size 0

The above exception was the direct cause of the following exception:

[36mray::DefaultActor.run()[39m (pid=57027, ip=127.0.0.1, actor_id=5bf67ed44f1870e964b6360401000000, repr=<flwr.simulation.ray_transport.ray_actor.DefaultActor object at 0x105d49a60>)
  File "/Users/Slaton/myvenv/flwr/lib/python3.9/site-packages/flwr/simulation/ray_transport/ray_actor.py", line 90, in run
    raise ClientException(str(message)) from ex
flwr.simulation.ray_transport.ray_actor.ClientException: 
>>>>>>>A ClientException occurred.('\n\tSomething went wrong when running your client run.\n\tClient 5 crashed when the DefaultActor was running its run.\n\tException triggered on the client side: Traceback (most recent call last):\n  File "/Users/Slaton/myvenv/flwr/lib/python3.9/site-packages/flwr/simulation/ray_transport/ray_actor.py", line 76, in run\n    job_results = job_fn(client)\n  File "/Users/Slaton/myvenv/flwr/lib/python3.9/site-packages/flwr/simulation/ray_transport/ray_client_proxy.py", line 207, in fit\n    return maybe_call_fit(\n  File "/Users/Slaton/myvenv/flwr/lib/python3.9/site-packages/flwr/client/client.py", line 234, in maybe_call_fit\n    return client.fit(fit_ins)\n  File "/Users/Slaton/myvenv/flwr/lib/python3.9/site-packages/flwr/client/numpy_client.py", line 238, in _fit\n    results = self.numpy_client.fit(parameters, ins.config)  # type: ignore\n  File "/Users/Slaton/Documents/grenoble-code/fl-flower/project3-result/client.py", line 39, in fit\n    self.set_parameters(parameters)\n  File "/Users/Slaton/Documents/grenoble-code/fl-flower/project3-result/client.py", line 31, in set_parameters\n    self.model.load_state_dict(state_dict, strict = False)\n  File "/Users/Slaton/myvenv/flwr/lib/python3.9/site-packages/torch/nn/modules/module.py", line 2139, in load_state_dict\n    load(self, state_dict)\n  File "/Users/Slaton/myvenv/flwr/lib/python3.9/site-packages/torch/nn/modules/module.py", line 2127, in load\n    load(child, child_state_dict, child_prefix)\n  File "/Users/Slaton/myvenv/flwr/lib/python3.9/site-packages/torch/nn/modules/module.py", line 2127, in load\n    load(child, child_state_dict, child_prefix)\n  File "/Users/Slaton/myvenv/flwr/lib/python3.9/site-packages/torch/nn/modules/module.py", line 2127, in load\n    load(child, child_state_dict, child_prefix)\n  File "/Users/Slaton/myvenv/flwr/lib/python3.9/site-packages/torch/nn/modules/module.py", line 2121, in load\n    module._load_from_state_dict(\n  File "/Users/Slaton/myvenv/flwr/lib/python3.9/site-packages/torch/nn/modules/batchnorm.py", line 114, in _load_from_state_dict\n    super()._load_from_state_dict(\n  File "/Users/Slaton/myvenv/flwr/lib/python3.9/site-packages/torch/nn/modules/module.py", line 2015, in _load_from_state_dict\n    input_param = input_param[0]\nIndexError: index 0 is out of bounds for dimension 0 with size 0\n',)
[2024-02-22 10:08:10,955][flwr][ERROR] - Traceback (most recent call last):
  File "/Users/Slaton/myvenv/flwr/lib/python3.9/site-packages/flwr/simulation/ray_transport/ray_client_proxy.py", line 151, in _submit_job
    res, updated_context = self.actor_pool.get_client_result(self.cid, timeout)
  File "/Users/Slaton/myvenv/flwr/lib/python3.9/site-packages/flwr/simulation/ray_transport/ray_actor.py", line 425, in get_client_result
    return self._fetch_future_result(cid)
  File "/Users/Slaton/myvenv/flwr/lib/python3.9/site-packages/flwr/simulation/ray_transport/ray_actor.py", line 306, in _fetch_future_result
    res_cid, res, updated_context = ray.get(
  File "/Users/Slaton/myvenv/flwr/lib/python3.9/site-packages/ray/_private/auto_init_hook.py", line 24, in auto_init_wrapper
    return fn(*args, **kwargs)
  File "/Users/Slaton/myvenv/flwr/lib/python3.9/site-packages/ray/_private/client_mode_hook.py", line 103, in wrapper
    return func(*args, **kwargs)
  File "/Users/Slaton/myvenv/flwr/lib/python3.9/site-packages/ray/_private/worker.py", line 2524, in get
    raise value.as_instanceof_cause()
ray.exceptions.RayTaskError(ClientException): [36mray::DefaultActor.run()[39m (pid=57028, ip=127.0.0.1, actor_id=4c7ac826f305fef553fc9eee01000000, repr=<flwr.simulation.ray_transport.ray_actor.DefaultActor object at 0x111511a00>)
  File "/Users/Slaton/myvenv/flwr/lib/python3.9/site-packages/flwr/simulation/ray_transport/ray_client_proxy.py", line 207, in fit
    return maybe_call_fit(
  File "/Users/Slaton/myvenv/flwr/lib/python3.9/site-packages/flwr/client/client.py", line 234, in maybe_call_fit
    return client.fit(fit_ins)
  File "/Users/Slaton/myvenv/flwr/lib/python3.9/site-packages/flwr/client/numpy_client.py", line 238, in _fit
    results = self.numpy_client.fit(parameters, ins.config)  # type: ignore
  File "/Users/Slaton/Documents/grenoble-code/fl-flower/project3-result/client.py", line 39, in fit
    self.set_parameters(parameters)
  File "/Users/Slaton/Documents/grenoble-code/fl-flower/project3-result/client.py", line 31, in set_parameters
    self.model.load_state_dict(state_dict, strict = False)
  File "/Users/Slaton/myvenv/flwr/lib/python3.9/site-packages/torch/nn/modules/module.py", line 2139, in load_state_dict
    load(self, state_dict)
  File "/Users/Slaton/myvenv/flwr/lib/python3.9/site-packages/torch/nn/modules/module.py", line 2127, in load
    load(child, child_state_dict, child_prefix)
  File "/Users/Slaton/myvenv/flwr/lib/python3.9/site-packages/torch/nn/modules/module.py", line 2127, in load
    load(child, child_state_dict, child_prefix)
  File "/Users/Slaton/myvenv/flwr/lib/python3.9/site-packages/torch/nn/modules/module.py", line 2127, in load
    load(child, child_state_dict, child_prefix)
  File "/Users/Slaton/myvenv/flwr/lib/python3.9/site-packages/torch/nn/modules/module.py", line 2121, in load
    module._load_from_state_dict(
  File "/Users/Slaton/myvenv/flwr/lib/python3.9/site-packages/torch/nn/modules/batchnorm.py", line 114, in _load_from_state_dict
    super()._load_from_state_dict(
  File "/Users/Slaton/myvenv/flwr/lib/python3.9/site-packages/torch/nn/modules/module.py", line 2015, in _load_from_state_dict
    input_param = input_param[0]
IndexError: index 0 is out of bounds for dimension 0 with size 0

The above exception was the direct cause of the following exception:

[36mray::DefaultActor.run()[39m (pid=57028, ip=127.0.0.1, actor_id=4c7ac826f305fef553fc9eee01000000, repr=<flwr.simulation.ray_transport.ray_actor.DefaultActor object at 0x111511a00>)
  File "/Users/Slaton/myvenv/flwr/lib/python3.9/site-packages/flwr/simulation/ray_transport/ray_actor.py", line 90, in run
    raise ClientException(str(message)) from ex
flwr.simulation.ray_transport.ray_actor.ClientException: 
>>>>>>>A ClientException occurred.('\n\tSomething went wrong when running your client run.\n\tClient 4 crashed when the DefaultActor was running its run.\n\tException triggered on the client side: Traceback (most recent call last):\n  File "/Users/Slaton/myvenv/flwr/lib/python3.9/site-packages/flwr/simulation/ray_transport/ray_actor.py", line 76, in run\n    job_results = job_fn(client)\n  File "/Users/Slaton/myvenv/flwr/lib/python3.9/site-packages/flwr/simulation/ray_transport/ray_client_proxy.py", line 207, in fit\n    return maybe_call_fit(\n  File "/Users/Slaton/myvenv/flwr/lib/python3.9/site-packages/flwr/client/client.py", line 234, in maybe_call_fit\n    return client.fit(fit_ins)\n  File "/Users/Slaton/myvenv/flwr/lib/python3.9/site-packages/flwr/client/numpy_client.py", line 238, in _fit\n    results = self.numpy_client.fit(parameters, ins.config)  # type: ignore\n  File "/Users/Slaton/Documents/grenoble-code/fl-flower/project3-result/client.py", line 39, in fit\n    self.set_parameters(parameters)\n  File "/Users/Slaton/Documents/grenoble-code/fl-flower/project3-result/client.py", line 31, in set_parameters\n    self.model.load_state_dict(state_dict, strict = False)\n  File "/Users/Slaton/myvenv/flwr/lib/python3.9/site-packages/torch/nn/modules/module.py", line 2139, in load_state_dict\n    load(self, state_dict)\n  File "/Users/Slaton/myvenv/flwr/lib/python3.9/site-packages/torch/nn/modules/module.py", line 2127, in load\n    load(child, child_state_dict, child_prefix)\n  File "/Users/Slaton/myvenv/flwr/lib/python3.9/site-packages/torch/nn/modules/module.py", line 2127, in load\n    load(child, child_state_dict, child_prefix)\n  File "/Users/Slaton/myvenv/flwr/lib/python3.9/site-packages/torch/nn/modules/module.py", line 2127, in load\n    load(child, child_state_dict, child_prefix)\n  File "/Users/Slaton/myvenv/flwr/lib/python3.9/site-packages/torch/nn/modules/module.py", line 2121, in load\n    module._load_from_state_dict(\n  File "/Users/Slaton/myvenv/flwr/lib/python3.9/site-packages/torch/nn/modules/batchnorm.py", line 114, in _load_from_state_dict\n    super()._load_from_state_dict(\n  File "/Users/Slaton/myvenv/flwr/lib/python3.9/site-packages/torch/nn/modules/module.py", line 2015, in _load_from_state_dict\n    input_param = input_param[0]\nIndexError: index 0 is out of bounds for dimension 0 with size 0\n',)

[2024-02-22 10:08:10,956][flwr][ERROR] - [36mray::DefaultActor.run()[39m (pid=57028, ip=127.0.0.1, actor_id=4c7ac826f305fef553fc9eee01000000, repr=<flwr.simulation.ray_transport.ray_actor.DefaultActor object at 0x111511a00>)
  File "/Users/Slaton/myvenv/flwr/lib/python3.9/site-packages/flwr/simulation/ray_transport/ray_client_proxy.py", line 207, in fit
    return maybe_call_fit(
  File "/Users/Slaton/myvenv/flwr/lib/python3.9/site-packages/flwr/client/client.py", line 234, in maybe_call_fit
    return client.fit(fit_ins)
  File "/Users/Slaton/myvenv/flwr/lib/python3.9/site-packages/flwr/client/numpy_client.py", line 238, in _fit
    results = self.numpy_client.fit(parameters, ins.config)  # type: ignore
  File "/Users/Slaton/Documents/grenoble-code/fl-flower/project3-result/client.py", line 39, in fit
    self.set_parameters(parameters)
  File "/Users/Slaton/Documents/grenoble-code/fl-flower/project3-result/client.py", line 31, in set_parameters
    self.model.load_state_dict(state_dict, strict = False)
  File "/Users/Slaton/myvenv/flwr/lib/python3.9/site-packages/torch/nn/modules/module.py", line 2139, in load_state_dict
    load(self, state_dict)
  File "/Users/Slaton/myvenv/flwr/lib/python3.9/site-packages/torch/nn/modules/module.py", line 2127, in load
    load(child, child_state_dict, child_prefix)
  File "/Users/Slaton/myvenv/flwr/lib/python3.9/site-packages/torch/nn/modules/module.py", line 2127, in load
    load(child, child_state_dict, child_prefix)
  File "/Users/Slaton/myvenv/flwr/lib/python3.9/site-packages/torch/nn/modules/module.py", line 2127, in load
    load(child, child_state_dict, child_prefix)
  File "/Users/Slaton/myvenv/flwr/lib/python3.9/site-packages/torch/nn/modules/module.py", line 2121, in load
    module._load_from_state_dict(
  File "/Users/Slaton/myvenv/flwr/lib/python3.9/site-packages/torch/nn/modules/batchnorm.py", line 114, in _load_from_state_dict
    super()._load_from_state_dict(
  File "/Users/Slaton/myvenv/flwr/lib/python3.9/site-packages/torch/nn/modules/module.py", line 2015, in _load_from_state_dict
    input_param = input_param[0]
IndexError: index 0 is out of bounds for dimension 0 with size 0

The above exception was the direct cause of the following exception:

[36mray::DefaultActor.run()[39m (pid=57028, ip=127.0.0.1, actor_id=4c7ac826f305fef553fc9eee01000000, repr=<flwr.simulation.ray_transport.ray_actor.DefaultActor object at 0x111511a00>)
  File "/Users/Slaton/myvenv/flwr/lib/python3.9/site-packages/flwr/simulation/ray_transport/ray_actor.py", line 90, in run
    raise ClientException(str(message)) from ex
flwr.simulation.ray_transport.ray_actor.ClientException: 
>>>>>>>A ClientException occurred.('\n\tSomething went wrong when running your client run.\n\tClient 4 crashed when the DefaultActor was running its run.\n\tException triggered on the client side: Traceback (most recent call last):\n  File "/Users/Slaton/myvenv/flwr/lib/python3.9/site-packages/flwr/simulation/ray_transport/ray_actor.py", line 76, in run\n    job_results = job_fn(client)\n  File "/Users/Slaton/myvenv/flwr/lib/python3.9/site-packages/flwr/simulation/ray_transport/ray_client_proxy.py", line 207, in fit\n    return maybe_call_fit(\n  File "/Users/Slaton/myvenv/flwr/lib/python3.9/site-packages/flwr/client/client.py", line 234, in maybe_call_fit\n    return client.fit(fit_ins)\n  File "/Users/Slaton/myvenv/flwr/lib/python3.9/site-packages/flwr/client/numpy_client.py", line 238, in _fit\n    results = self.numpy_client.fit(parameters, ins.config)  # type: ignore\n  File "/Users/Slaton/Documents/grenoble-code/fl-flower/project3-result/client.py", line 39, in fit\n    self.set_parameters(parameters)\n  File "/Users/Slaton/Documents/grenoble-code/fl-flower/project3-result/client.py", line 31, in set_parameters\n    self.model.load_state_dict(state_dict, strict = False)\n  File "/Users/Slaton/myvenv/flwr/lib/python3.9/site-packages/torch/nn/modules/module.py", line 2139, in load_state_dict\n    load(self, state_dict)\n  File "/Users/Slaton/myvenv/flwr/lib/python3.9/site-packages/torch/nn/modules/module.py", line 2127, in load\n    load(child, child_state_dict, child_prefix)\n  File "/Users/Slaton/myvenv/flwr/lib/python3.9/site-packages/torch/nn/modules/module.py", line 2127, in load\n    load(child, child_state_dict, child_prefix)\n  File "/Users/Slaton/myvenv/flwr/lib/python3.9/site-packages/torch/nn/modules/module.py", line 2127, in load\n    load(child, child_state_dict, child_prefix)\n  File "/Users/Slaton/myvenv/flwr/lib/python3.9/site-packages/torch/nn/modules/module.py", line 2121, in load\n    module._load_from_state_dict(\n  File "/Users/Slaton/myvenv/flwr/lib/python3.9/site-packages/torch/nn/modules/batchnorm.py", line 114, in _load_from_state_dict\n    super()._load_from_state_dict(\n  File "/Users/Slaton/myvenv/flwr/lib/python3.9/site-packages/torch/nn/modules/module.py", line 2015, in _load_from_state_dict\n    input_param = input_param[0]\nIndexError: index 0 is out of bounds for dimension 0 with size 0\n',)
[2024-02-22 10:08:10,984][flwr][ERROR] - Traceback (most recent call last):
  File "/Users/Slaton/myvenv/flwr/lib/python3.9/site-packages/flwr/simulation/ray_transport/ray_client_proxy.py", line 151, in _submit_job
    res, updated_context = self.actor_pool.get_client_result(self.cid, timeout)
  File "/Users/Slaton/myvenv/flwr/lib/python3.9/site-packages/flwr/simulation/ray_transport/ray_actor.py", line 425, in get_client_result
    return self._fetch_future_result(cid)
  File "/Users/Slaton/myvenv/flwr/lib/python3.9/site-packages/flwr/simulation/ray_transport/ray_actor.py", line 306, in _fetch_future_result
    res_cid, res, updated_context = ray.get(
  File "/Users/Slaton/myvenv/flwr/lib/python3.9/site-packages/ray/_private/auto_init_hook.py", line 24, in auto_init_wrapper
    return fn(*args, **kwargs)
  File "/Users/Slaton/myvenv/flwr/lib/python3.9/site-packages/ray/_private/client_mode_hook.py", line 103, in wrapper
    return func(*args, **kwargs)
  File "/Users/Slaton/myvenv/flwr/lib/python3.9/site-packages/ray/_private/worker.py", line 2524, in get
    raise value.as_instanceof_cause()
ray.exceptions.RayTaskError(ClientException): [36mray::DefaultActor.run()[39m (pid=57027, ip=127.0.0.1, actor_id=5bf67ed44f1870e964b6360401000000, repr=<flwr.simulation.ray_transport.ray_actor.DefaultActor object at 0x105d49a60>)
  File "/Users/Slaton/myvenv/flwr/lib/python3.9/site-packages/flwr/simulation/ray_transport/ray_client_proxy.py", line 207, in fit
    return maybe_call_fit(
  File "/Users/Slaton/myvenv/flwr/lib/python3.9/site-packages/flwr/client/client.py", line 234, in maybe_call_fit
    return client.fit(fit_ins)
  File "/Users/Slaton/myvenv/flwr/lib/python3.9/site-packages/flwr/client/numpy_client.py", line 238, in _fit
    results = self.numpy_client.fit(parameters, ins.config)  # type: ignore
  File "/Users/Slaton/Documents/grenoble-code/fl-flower/project3-result/client.py", line 39, in fit
    self.set_parameters(parameters)
  File "/Users/Slaton/Documents/grenoble-code/fl-flower/project3-result/client.py", line 31, in set_parameters
    self.model.load_state_dict(state_dict, strict = False)
  File "/Users/Slaton/myvenv/flwr/lib/python3.9/site-packages/torch/nn/modules/module.py", line 2139, in load_state_dict
    load(self, state_dict)
  File "/Users/Slaton/myvenv/flwr/lib/python3.9/site-packages/torch/nn/modules/module.py", line 2127, in load
    load(child, child_state_dict, child_prefix)
  File "/Users/Slaton/myvenv/flwr/lib/python3.9/site-packages/torch/nn/modules/module.py", line 2127, in load
    load(child, child_state_dict, child_prefix)
  File "/Users/Slaton/myvenv/flwr/lib/python3.9/site-packages/torch/nn/modules/module.py", line 2127, in load
    load(child, child_state_dict, child_prefix)
  File "/Users/Slaton/myvenv/flwr/lib/python3.9/site-packages/torch/nn/modules/module.py", line 2121, in load
    module._load_from_state_dict(
  File "/Users/Slaton/myvenv/flwr/lib/python3.9/site-packages/torch/nn/modules/batchnorm.py", line 114, in _load_from_state_dict
    super()._load_from_state_dict(
  File "/Users/Slaton/myvenv/flwr/lib/python3.9/site-packages/torch/nn/modules/module.py", line 2015, in _load_from_state_dict
    input_param = input_param[0]
IndexError: index 0 is out of bounds for dimension 0 with size 0

The above exception was the direct cause of the following exception:

[36mray::DefaultActor.run()[39m (pid=57027, ip=127.0.0.1, actor_id=5bf67ed44f1870e964b6360401000000, repr=<flwr.simulation.ray_transport.ray_actor.DefaultActor object at 0x105d49a60>)
  File "/Users/Slaton/myvenv/flwr/lib/python3.9/site-packages/flwr/simulation/ray_transport/ray_actor.py", line 90, in run
    raise ClientException(str(message)) from ex
flwr.simulation.ray_transport.ray_actor.ClientException: 
>>>>>>>A ClientException occurred.('\n\tSomething went wrong when running your client run.\n\tClient 1 crashed when the DefaultActor was running its run.\n\tException triggered on the client side: Traceback (most recent call last):\n  File "/Users/Slaton/myvenv/flwr/lib/python3.9/site-packages/flwr/simulation/ray_transport/ray_actor.py", line 76, in run\n    job_results = job_fn(client)\n  File "/Users/Slaton/myvenv/flwr/lib/python3.9/site-packages/flwr/simulation/ray_transport/ray_client_proxy.py", line 207, in fit\n    return maybe_call_fit(\n  File "/Users/Slaton/myvenv/flwr/lib/python3.9/site-packages/flwr/client/client.py", line 234, in maybe_call_fit\n    return client.fit(fit_ins)\n  File "/Users/Slaton/myvenv/flwr/lib/python3.9/site-packages/flwr/client/numpy_client.py", line 238, in _fit\n    results = self.numpy_client.fit(parameters, ins.config)  # type: ignore\n  File "/Users/Slaton/Documents/grenoble-code/fl-flower/project3-result/client.py", line 39, in fit\n    self.set_parameters(parameters)\n  File "/Users/Slaton/Documents/grenoble-code/fl-flower/project3-result/client.py", line 31, in set_parameters\n    self.model.load_state_dict(state_dict, strict = False)\n  File "/Users/Slaton/myvenv/flwr/lib/python3.9/site-packages/torch/nn/modules/module.py", line 2139, in load_state_dict\n    load(self, state_dict)\n  File "/Users/Slaton/myvenv/flwr/lib/python3.9/site-packages/torch/nn/modules/module.py", line 2127, in load\n    load(child, child_state_dict, child_prefix)\n  File "/Users/Slaton/myvenv/flwr/lib/python3.9/site-packages/torch/nn/modules/module.py", line 2127, in load\n    load(child, child_state_dict, child_prefix)\n  File "/Users/Slaton/myvenv/flwr/lib/python3.9/site-packages/torch/nn/modules/module.py", line 2127, in load\n    load(child, child_state_dict, child_prefix)\n  File "/Users/Slaton/myvenv/flwr/lib/python3.9/site-packages/torch/nn/modules/module.py", line 2121, in load\n    module._load_from_state_dict(\n  File "/Users/Slaton/myvenv/flwr/lib/python3.9/site-packages/torch/nn/modules/batchnorm.py", line 114, in _load_from_state_dict\n    super()._load_from_state_dict(\n  File "/Users/Slaton/myvenv/flwr/lib/python3.9/site-packages/torch/nn/modules/module.py", line 2015, in _load_from_state_dict\n    input_param = input_param[0]\nIndexError: index 0 is out of bounds for dimension 0 with size 0\n',)

[2024-02-22 10:08:11,969][flwr][ERROR] - [36mray::DefaultActor.run()[39m (pid=57027, ip=127.0.0.1, actor_id=5bf67ed44f1870e964b6360401000000, repr=<flwr.simulation.ray_transport.ray_actor.DefaultActor object at 0x105d49a60>)
  File "/Users/Slaton/myvenv/flwr/lib/python3.9/site-packages/flwr/simulation/ray_transport/ray_client_proxy.py", line 207, in fit
    return maybe_call_fit(
  File "/Users/Slaton/myvenv/flwr/lib/python3.9/site-packages/flwr/client/client.py", line 234, in maybe_call_fit
    return client.fit(fit_ins)
  File "/Users/Slaton/myvenv/flwr/lib/python3.9/site-packages/flwr/client/numpy_client.py", line 238, in _fit
    results = self.numpy_client.fit(parameters, ins.config)  # type: ignore
  File "/Users/Slaton/Documents/grenoble-code/fl-flower/project3-result/client.py", line 39, in fit
    self.set_parameters(parameters)
  File "/Users/Slaton/Documents/grenoble-code/fl-flower/project3-result/client.py", line 31, in set_parameters
    self.model.load_state_dict(state_dict, strict = False)
  File "/Users/Slaton/myvenv/flwr/lib/python3.9/site-packages/torch/nn/modules/module.py", line 2139, in load_state_dict
    load(self, state_dict)
  File "/Users/Slaton/myvenv/flwr/lib/python3.9/site-packages/torch/nn/modules/module.py", line 2127, in load
    load(child, child_state_dict, child_prefix)
  File "/Users/Slaton/myvenv/flwr/lib/python3.9/site-packages/torch/nn/modules/module.py", line 2127, in load
    load(child, child_state_dict, child_prefix)
  File "/Users/Slaton/myvenv/flwr/lib/python3.9/site-packages/torch/nn/modules/module.py", line 2127, in load
    load(child, child_state_dict, child_prefix)
  File "/Users/Slaton/myvenv/flwr/lib/python3.9/site-packages/torch/nn/modules/module.py", line 2121, in load
    module._load_from_state_dict(
  File "/Users/Slaton/myvenv/flwr/lib/python3.9/site-packages/torch/nn/modules/batchnorm.py", line 114, in _load_from_state_dict
    super()._load_from_state_dict(
  File "/Users/Slaton/myvenv/flwr/lib/python3.9/site-packages/torch/nn/modules/module.py", line 2015, in _load_from_state_dict
    input_param = input_param[0]
IndexError: index 0 is out of bounds for dimension 0 with size 0

The above exception was the direct cause of the following exception:

[36mray::DefaultActor.run()[39m (pid=57027, ip=127.0.0.1, actor_id=5bf67ed44f1870e964b6360401000000, repr=<flwr.simulation.ray_transport.ray_actor.DefaultActor object at 0x105d49a60>)
  File "/Users/Slaton/myvenv/flwr/lib/python3.9/site-packages/flwr/simulation/ray_transport/ray_actor.py", line 90, in run
    raise ClientException(str(message)) from ex
flwr.simulation.ray_transport.ray_actor.ClientException: 
>>>>>>>A ClientException occurred.('\n\tSomething went wrong when running your client run.\n\tClient 1 crashed when the DefaultActor was running its run.\n\tException triggered on the client side: Traceback (most recent call last):\n  File "/Users/Slaton/myvenv/flwr/lib/python3.9/site-packages/flwr/simulation/ray_transport/ray_actor.py", line 76, in run\n    job_results = job_fn(client)\n  File "/Users/Slaton/myvenv/flwr/lib/python3.9/site-packages/flwr/simulation/ray_transport/ray_client_proxy.py", line 207, in fit\n    return maybe_call_fit(\n  File "/Users/Slaton/myvenv/flwr/lib/python3.9/site-packages/flwr/client/client.py", line 234, in maybe_call_fit\n    return client.fit(fit_ins)\n  File "/Users/Slaton/myvenv/flwr/lib/python3.9/site-packages/flwr/client/numpy_client.py", line 238, in _fit\n    results = self.numpy_client.fit(parameters, ins.config)  # type: ignore\n  File "/Users/Slaton/Documents/grenoble-code/fl-flower/project3-result/client.py", line 39, in fit\n    self.set_parameters(parameters)\n  File "/Users/Slaton/Documents/grenoble-code/fl-flower/project3-result/client.py", line 31, in set_parameters\n    self.model.load_state_dict(state_dict, strict = False)\n  File "/Users/Slaton/myvenv/flwr/lib/python3.9/site-packages/torch/nn/modules/module.py", line 2139, in load_state_dict\n    load(self, state_dict)\n  File "/Users/Slaton/myvenv/flwr/lib/python3.9/site-packages/torch/nn/modules/module.py", line 2127, in load\n    load(child, child_state_dict, child_prefix)\n  File "/Users/Slaton/myvenv/flwr/lib/python3.9/site-packages/torch/nn/modules/module.py", line 2127, in load\n    load(child, child_state_dict, child_prefix)\n  File "/Users/Slaton/myvenv/flwr/lib/python3.9/site-packages/torch/nn/modules/module.py", line 2127, in load\n    load(child, child_state_dict, child_prefix)\n  File "/Users/Slaton/myvenv/flwr/lib/python3.9/site-packages/torch/nn/modules/module.py", line 2121, in load\n    module._load_from_state_dict(\n  File "/Users/Slaton/myvenv/flwr/lib/python3.9/site-packages/torch/nn/modules/batchnorm.py", line 114, in _load_from_state_dict\n    super()._load_from_state_dict(\n  File "/Users/Slaton/myvenv/flwr/lib/python3.9/site-packages/torch/nn/modules/module.py", line 2015, in _load_from_state_dict\n    input_param = input_param[0]\nIndexError: index 0 is out of bounds for dimension 0 with size 0\n',)
[2024-02-22 10:08:11,991][flwr][ERROR] - Traceback (most recent call last):
  File "/Users/Slaton/myvenv/flwr/lib/python3.9/site-packages/flwr/simulation/ray_transport/ray_client_proxy.py", line 151, in _submit_job
    res, updated_context = self.actor_pool.get_client_result(self.cid, timeout)
  File "/Users/Slaton/myvenv/flwr/lib/python3.9/site-packages/flwr/simulation/ray_transport/ray_actor.py", line 425, in get_client_result
    return self._fetch_future_result(cid)
  File "/Users/Slaton/myvenv/flwr/lib/python3.9/site-packages/flwr/simulation/ray_transport/ray_actor.py", line 306, in _fetch_future_result
    res_cid, res, updated_context = ray.get(
  File "/Users/Slaton/myvenv/flwr/lib/python3.9/site-packages/ray/_private/auto_init_hook.py", line 24, in auto_init_wrapper
    return fn(*args, **kwargs)
  File "/Users/Slaton/myvenv/flwr/lib/python3.9/site-packages/ray/_private/client_mode_hook.py", line 103, in wrapper
    return func(*args, **kwargs)
  File "/Users/Slaton/myvenv/flwr/lib/python3.9/site-packages/ray/_private/worker.py", line 2524, in get
    raise value.as_instanceof_cause()
ray.exceptions.RayTaskError(ClientException): [36mray::DefaultActor.run()[39m (pid=57028, ip=127.0.0.1, actor_id=4c7ac826f305fef553fc9eee01000000, repr=<flwr.simulation.ray_transport.ray_actor.DefaultActor object at 0x111511a00>)
  File "/Users/Slaton/myvenv/flwr/lib/python3.9/site-packages/flwr/simulation/ray_transport/ray_client_proxy.py", line 207, in fit
    return maybe_call_fit(
  File "/Users/Slaton/myvenv/flwr/lib/python3.9/site-packages/flwr/client/client.py", line 234, in maybe_call_fit
    return client.fit(fit_ins)
  File "/Users/Slaton/myvenv/flwr/lib/python3.9/site-packages/flwr/client/numpy_client.py", line 238, in _fit
    results = self.numpy_client.fit(parameters, ins.config)  # type: ignore
  File "/Users/Slaton/Documents/grenoble-code/fl-flower/project3-result/client.py", line 39, in fit
    self.set_parameters(parameters)
  File "/Users/Slaton/Documents/grenoble-code/fl-flower/project3-result/client.py", line 31, in set_parameters
    self.model.load_state_dict(state_dict, strict = False)
  File "/Users/Slaton/myvenv/flwr/lib/python3.9/site-packages/torch/nn/modules/module.py", line 2139, in load_state_dict
    load(self, state_dict)
  File "/Users/Slaton/myvenv/flwr/lib/python3.9/site-packages/torch/nn/modules/module.py", line 2127, in load
    load(child, child_state_dict, child_prefix)
  File "/Users/Slaton/myvenv/flwr/lib/python3.9/site-packages/torch/nn/modules/module.py", line 2127, in load
    load(child, child_state_dict, child_prefix)
  File "/Users/Slaton/myvenv/flwr/lib/python3.9/site-packages/torch/nn/modules/module.py", line 2127, in load
    load(child, child_state_dict, child_prefix)
  File "/Users/Slaton/myvenv/flwr/lib/python3.9/site-packages/torch/nn/modules/module.py", line 2121, in load
    module._load_from_state_dict(
  File "/Users/Slaton/myvenv/flwr/lib/python3.9/site-packages/torch/nn/modules/batchnorm.py", line 114, in _load_from_state_dict
    super()._load_from_state_dict(
  File "/Users/Slaton/myvenv/flwr/lib/python3.9/site-packages/torch/nn/modules/module.py", line 2015, in _load_from_state_dict
    input_param = input_param[0]
IndexError: index 0 is out of bounds for dimension 0 with size 0

The above exception was the direct cause of the following exception:

[36mray::DefaultActor.run()[39m (pid=57028, ip=127.0.0.1, actor_id=4c7ac826f305fef553fc9eee01000000, repr=<flwr.simulation.ray_transport.ray_actor.DefaultActor object at 0x111511a00>)
  File "/Users/Slaton/myvenv/flwr/lib/python3.9/site-packages/flwr/simulation/ray_transport/ray_actor.py", line 90, in run
    raise ClientException(str(message)) from ex
flwr.simulation.ray_transport.ray_actor.ClientException: 
>>>>>>>A ClientException occurred.('\n\tSomething went wrong when running your client run.\n\tClient 6 crashed when the DefaultActor was running its run.\n\tException triggered on the client side: Traceback (most recent call last):\n  File "/Users/Slaton/myvenv/flwr/lib/python3.9/site-packages/flwr/simulation/ray_transport/ray_actor.py", line 76, in run\n    job_results = job_fn(client)\n  File "/Users/Slaton/myvenv/flwr/lib/python3.9/site-packages/flwr/simulation/ray_transport/ray_client_proxy.py", line 207, in fit\n    return maybe_call_fit(\n  File "/Users/Slaton/myvenv/flwr/lib/python3.9/site-packages/flwr/client/client.py", line 234, in maybe_call_fit\n    return client.fit(fit_ins)\n  File "/Users/Slaton/myvenv/flwr/lib/python3.9/site-packages/flwr/client/numpy_client.py", line 238, in _fit\n    results = self.numpy_client.fit(parameters, ins.config)  # type: ignore\n  File "/Users/Slaton/Documents/grenoble-code/fl-flower/project3-result/client.py", line 39, in fit\n    self.set_parameters(parameters)\n  File "/Users/Slaton/Documents/grenoble-code/fl-flower/project3-result/client.py", line 31, in set_parameters\n    self.model.load_state_dict(state_dict, strict = False)\n  File "/Users/Slaton/myvenv/flwr/lib/python3.9/site-packages/torch/nn/modules/module.py", line 2139, in load_state_dict\n    load(self, state_dict)\n  File "/Users/Slaton/myvenv/flwr/lib/python3.9/site-packages/torch/nn/modules/module.py", line 2127, in load\n    load(child, child_state_dict, child_prefix)\n  File "/Users/Slaton/myvenv/flwr/lib/python3.9/site-packages/torch/nn/modules/module.py", line 2127, in load\n    load(child, child_state_dict, child_prefix)\n  File "/Users/Slaton/myvenv/flwr/lib/python3.9/site-packages/torch/nn/modules/module.py", line 2127, in load\n    load(child, child_state_dict, child_prefix)\n  File "/Users/Slaton/myvenv/flwr/lib/python3.9/site-packages/torch/nn/modules/module.py", line 2121, in load\n    module._load_from_state_dict(\n  File "/Users/Slaton/myvenv/flwr/lib/python3.9/site-packages/torch/nn/modules/batchnorm.py", line 114, in _load_from_state_dict\n    super()._load_from_state_dict(\n  File "/Users/Slaton/myvenv/flwr/lib/python3.9/site-packages/torch/nn/modules/module.py", line 2015, in _load_from_state_dict\n    input_param = input_param[0]\nIndexError: index 0 is out of bounds for dimension 0 with size 0\n',)

[2024-02-22 10:08:13,002][flwr][ERROR] - [36mray::DefaultActor.run()[39m (pid=57028, ip=127.0.0.1, actor_id=4c7ac826f305fef553fc9eee01000000, repr=<flwr.simulation.ray_transport.ray_actor.DefaultActor object at 0x111511a00>)
  File "/Users/Slaton/myvenv/flwr/lib/python3.9/site-packages/flwr/simulation/ray_transport/ray_client_proxy.py", line 207, in fit
    return maybe_call_fit(
  File "/Users/Slaton/myvenv/flwr/lib/python3.9/site-packages/flwr/client/client.py", line 234, in maybe_call_fit
    return client.fit(fit_ins)
  File "/Users/Slaton/myvenv/flwr/lib/python3.9/site-packages/flwr/client/numpy_client.py", line 238, in _fit
    results = self.numpy_client.fit(parameters, ins.config)  # type: ignore
  File "/Users/Slaton/Documents/grenoble-code/fl-flower/project3-result/client.py", line 39, in fit
    self.set_parameters(parameters)
  File "/Users/Slaton/Documents/grenoble-code/fl-flower/project3-result/client.py", line 31, in set_parameters
    self.model.load_state_dict(state_dict, strict = False)
  File "/Users/Slaton/myvenv/flwr/lib/python3.9/site-packages/torch/nn/modules/module.py", line 2139, in load_state_dict
    load(self, state_dict)
  File "/Users/Slaton/myvenv/flwr/lib/python3.9/site-packages/torch/nn/modules/module.py", line 2127, in load
    load(child, child_state_dict, child_prefix)
  File "/Users/Slaton/myvenv/flwr/lib/python3.9/site-packages/torch/nn/modules/module.py", line 2127, in load
    load(child, child_state_dict, child_prefix)
  File "/Users/Slaton/myvenv/flwr/lib/python3.9/site-packages/torch/nn/modules/module.py", line 2127, in load
    load(child, child_state_dict, child_prefix)
  File "/Users/Slaton/myvenv/flwr/lib/python3.9/site-packages/torch/nn/modules/module.py", line 2121, in load
    module._load_from_state_dict(
  File "/Users/Slaton/myvenv/flwr/lib/python3.9/site-packages/torch/nn/modules/batchnorm.py", line 114, in _load_from_state_dict
    super()._load_from_state_dict(
  File "/Users/Slaton/myvenv/flwr/lib/python3.9/site-packages/torch/nn/modules/module.py", line 2015, in _load_from_state_dict
    input_param = input_param[0]
IndexError: index 0 is out of bounds for dimension 0 with size 0

The above exception was the direct cause of the following exception:

[36mray::DefaultActor.run()[39m (pid=57028, ip=127.0.0.1, actor_id=4c7ac826f305fef553fc9eee01000000, repr=<flwr.simulation.ray_transport.ray_actor.DefaultActor object at 0x111511a00>)
  File "/Users/Slaton/myvenv/flwr/lib/python3.9/site-packages/flwr/simulation/ray_transport/ray_actor.py", line 90, in run
    raise ClientException(str(message)) from ex
flwr.simulation.ray_transport.ray_actor.ClientException: 
>>>>>>>A ClientException occurred.('\n\tSomething went wrong when running your client run.\n\tClient 6 crashed when the DefaultActor was running its run.\n\tException triggered on the client side: Traceback (most recent call last):\n  File "/Users/Slaton/myvenv/flwr/lib/python3.9/site-packages/flwr/simulation/ray_transport/ray_actor.py", line 76, in run\n    job_results = job_fn(client)\n  File "/Users/Slaton/myvenv/flwr/lib/python3.9/site-packages/flwr/simulation/ray_transport/ray_client_proxy.py", line 207, in fit\n    return maybe_call_fit(\n  File "/Users/Slaton/myvenv/flwr/lib/python3.9/site-packages/flwr/client/client.py", line 234, in maybe_call_fit\n    return client.fit(fit_ins)\n  File "/Users/Slaton/myvenv/flwr/lib/python3.9/site-packages/flwr/client/numpy_client.py", line 238, in _fit\n    results = self.numpy_client.fit(parameters, ins.config)  # type: ignore\n  File "/Users/Slaton/Documents/grenoble-code/fl-flower/project3-result/client.py", line 39, in fit\n    self.set_parameters(parameters)\n  File "/Users/Slaton/Documents/grenoble-code/fl-flower/project3-result/client.py", line 31, in set_parameters\n    self.model.load_state_dict(state_dict, strict = False)\n  File "/Users/Slaton/myvenv/flwr/lib/python3.9/site-packages/torch/nn/modules/module.py", line 2139, in load_state_dict\n    load(self, state_dict)\n  File "/Users/Slaton/myvenv/flwr/lib/python3.9/site-packages/torch/nn/modules/module.py", line 2127, in load\n    load(child, child_state_dict, child_prefix)\n  File "/Users/Slaton/myvenv/flwr/lib/python3.9/site-packages/torch/nn/modules/module.py", line 2127, in load\n    load(child, child_state_dict, child_prefix)\n  File "/Users/Slaton/myvenv/flwr/lib/python3.9/site-packages/torch/nn/modules/module.py", line 2127, in load\n    load(child, child_state_dict, child_prefix)\n  File "/Users/Slaton/myvenv/flwr/lib/python3.9/site-packages/torch/nn/modules/module.py", line 2121, in load\n    module._load_from_state_dict(\n  File "/Users/Slaton/myvenv/flwr/lib/python3.9/site-packages/torch/nn/modules/batchnorm.py", line 114, in _load_from_state_dict\n    super()._load_from_state_dict(\n  File "/Users/Slaton/myvenv/flwr/lib/python3.9/site-packages/torch/nn/modules/module.py", line 2015, in _load_from_state_dict\n    input_param = input_param[0]\nIndexError: index 0 is out of bounds for dimension 0 with size 0\n',)
[2024-02-22 10:08:13,021][flwr][ERROR] - Traceback (most recent call last):
  File "/Users/Slaton/myvenv/flwr/lib/python3.9/site-packages/flwr/simulation/ray_transport/ray_client_proxy.py", line 151, in _submit_job
    res, updated_context = self.actor_pool.get_client_result(self.cid, timeout)
  File "/Users/Slaton/myvenv/flwr/lib/python3.9/site-packages/flwr/simulation/ray_transport/ray_actor.py", line 425, in get_client_result
    return self._fetch_future_result(cid)
  File "/Users/Slaton/myvenv/flwr/lib/python3.9/site-packages/flwr/simulation/ray_transport/ray_actor.py", line 306, in _fetch_future_result
    res_cid, res, updated_context = ray.get(
  File "/Users/Slaton/myvenv/flwr/lib/python3.9/site-packages/ray/_private/auto_init_hook.py", line 24, in auto_init_wrapper
    return fn(*args, **kwargs)
  File "/Users/Slaton/myvenv/flwr/lib/python3.9/site-packages/ray/_private/client_mode_hook.py", line 103, in wrapper
    return func(*args, **kwargs)
  File "/Users/Slaton/myvenv/flwr/lib/python3.9/site-packages/ray/_private/worker.py", line 2524, in get
    raise value.as_instanceof_cause()
ray.exceptions.RayTaskError(ClientException): [36mray::DefaultActor.run()[39m (pid=57027, ip=127.0.0.1, actor_id=5bf67ed44f1870e964b6360401000000, repr=<flwr.simulation.ray_transport.ray_actor.DefaultActor object at 0x105d49a60>)
  File "/Users/Slaton/myvenv/flwr/lib/python3.9/site-packages/flwr/simulation/ray_transport/ray_client_proxy.py", line 207, in fit
    return maybe_call_fit(
  File "/Users/Slaton/myvenv/flwr/lib/python3.9/site-packages/flwr/client/client.py", line 234, in maybe_call_fit
    return client.fit(fit_ins)
  File "/Users/Slaton/myvenv/flwr/lib/python3.9/site-packages/flwr/client/numpy_client.py", line 238, in _fit
    results = self.numpy_client.fit(parameters, ins.config)  # type: ignore
  File "/Users/Slaton/Documents/grenoble-code/fl-flower/project3-result/client.py", line 39, in fit
    self.set_parameters(parameters)
  File "/Users/Slaton/Documents/grenoble-code/fl-flower/project3-result/client.py", line 31, in set_parameters
    self.model.load_state_dict(state_dict, strict = False)
  File "/Users/Slaton/myvenv/flwr/lib/python3.9/site-packages/torch/nn/modules/module.py", line 2139, in load_state_dict
    load(self, state_dict)
  File "/Users/Slaton/myvenv/flwr/lib/python3.9/site-packages/torch/nn/modules/module.py", line 2127, in load
    load(child, child_state_dict, child_prefix)
  File "/Users/Slaton/myvenv/flwr/lib/python3.9/site-packages/torch/nn/modules/module.py", line 2127, in load
    load(child, child_state_dict, child_prefix)
  File "/Users/Slaton/myvenv/flwr/lib/python3.9/site-packages/torch/nn/modules/module.py", line 2127, in load
    load(child, child_state_dict, child_prefix)
  File "/Users/Slaton/myvenv/flwr/lib/python3.9/site-packages/torch/nn/modules/module.py", line 2121, in load
    module._load_from_state_dict(
  File "/Users/Slaton/myvenv/flwr/lib/python3.9/site-packages/torch/nn/modules/batchnorm.py", line 114, in _load_from_state_dict
    super()._load_from_state_dict(
  File "/Users/Slaton/myvenv/flwr/lib/python3.9/site-packages/torch/nn/modules/module.py", line 2015, in _load_from_state_dict
    input_param = input_param[0]
IndexError: index 0 is out of bounds for dimension 0 with size 0

The above exception was the direct cause of the following exception:

[36mray::DefaultActor.run()[39m (pid=57027, ip=127.0.0.1, actor_id=5bf67ed44f1870e964b6360401000000, repr=<flwr.simulation.ray_transport.ray_actor.DefaultActor object at 0x105d49a60>)
  File "/Users/Slaton/myvenv/flwr/lib/python3.9/site-packages/flwr/simulation/ray_transport/ray_actor.py", line 90, in run
    raise ClientException(str(message)) from ex
flwr.simulation.ray_transport.ray_actor.ClientException: 
>>>>>>>A ClientException occurred.('\n\tSomething went wrong when running your client run.\n\tClient 0 crashed when the DefaultActor was running its run.\n\tException triggered on the client side: Traceback (most recent call last):\n  File "/Users/Slaton/myvenv/flwr/lib/python3.9/site-packages/flwr/simulation/ray_transport/ray_actor.py", line 76, in run\n    job_results = job_fn(client)\n  File "/Users/Slaton/myvenv/flwr/lib/python3.9/site-packages/flwr/simulation/ray_transport/ray_client_proxy.py", line 207, in fit\n    return maybe_call_fit(\n  File "/Users/Slaton/myvenv/flwr/lib/python3.9/site-packages/flwr/client/client.py", line 234, in maybe_call_fit\n    return client.fit(fit_ins)\n  File "/Users/Slaton/myvenv/flwr/lib/python3.9/site-packages/flwr/client/numpy_client.py", line 238, in _fit\n    results = self.numpy_client.fit(parameters, ins.config)  # type: ignore\n  File "/Users/Slaton/Documents/grenoble-code/fl-flower/project3-result/client.py", line 39, in fit\n    self.set_parameters(parameters)\n  File "/Users/Slaton/Documents/grenoble-code/fl-flower/project3-result/client.py", line 31, in set_parameters\n    self.model.load_state_dict(state_dict, strict = False)\n  File "/Users/Slaton/myvenv/flwr/lib/python3.9/site-packages/torch/nn/modules/module.py", line 2139, in load_state_dict\n    load(self, state_dict)\n  File "/Users/Slaton/myvenv/flwr/lib/python3.9/site-packages/torch/nn/modules/module.py", line 2127, in load\n    load(child, child_state_dict, child_prefix)\n  File "/Users/Slaton/myvenv/flwr/lib/python3.9/site-packages/torch/nn/modules/module.py", line 2127, in load\n    load(child, child_state_dict, child_prefix)\n  File "/Users/Slaton/myvenv/flwr/lib/python3.9/site-packages/torch/nn/modules/module.py", line 2127, in load\n    load(child, child_state_dict, child_prefix)\n  File "/Users/Slaton/myvenv/flwr/lib/python3.9/site-packages/torch/nn/modules/module.py", line 2121, in load\n    module._load_from_state_dict(\n  File "/Users/Slaton/myvenv/flwr/lib/python3.9/site-packages/torch/nn/modules/batchnorm.py", line 114, in _load_from_state_dict\n    super()._load_from_state_dict(\n  File "/Users/Slaton/myvenv/flwr/lib/python3.9/site-packages/torch/nn/modules/module.py", line 2015, in _load_from_state_dict\n    input_param = input_param[0]\nIndexError: index 0 is out of bounds for dimension 0 with size 0\n',)

[2024-02-22 10:08:13,022][flwr][ERROR] - Traceback (most recent call last):
  File "/Users/Slaton/myvenv/flwr/lib/python3.9/site-packages/flwr/simulation/ray_transport/ray_client_proxy.py", line 151, in _submit_job
    res, updated_context = self.actor_pool.get_client_result(self.cid, timeout)
  File "/Users/Slaton/myvenv/flwr/lib/python3.9/site-packages/flwr/simulation/ray_transport/ray_actor.py", line 425, in get_client_result
    return self._fetch_future_result(cid)
  File "/Users/Slaton/myvenv/flwr/lib/python3.9/site-packages/flwr/simulation/ray_transport/ray_actor.py", line 306, in _fetch_future_result
    res_cid, res, updated_context = ray.get(
  File "/Users/Slaton/myvenv/flwr/lib/python3.9/site-packages/ray/_private/auto_init_hook.py", line 24, in auto_init_wrapper
    return fn(*args, **kwargs)
  File "/Users/Slaton/myvenv/flwr/lib/python3.9/site-packages/ray/_private/client_mode_hook.py", line 103, in wrapper
    return func(*args, **kwargs)
  File "/Users/Slaton/myvenv/flwr/lib/python3.9/site-packages/ray/_private/worker.py", line 2524, in get
    raise value.as_instanceof_cause()
ray.exceptions.RayTaskError(ClientException): [36mray::DefaultActor.run()[39m (pid=57028, ip=127.0.0.1, actor_id=4c7ac826f305fef553fc9eee01000000, repr=<flwr.simulation.ray_transport.ray_actor.DefaultActor object at 0x111511a00>)
  File "/Users/Slaton/myvenv/flwr/lib/python3.9/site-packages/flwr/simulation/ray_transport/ray_client_proxy.py", line 207, in fit
    return maybe_call_fit(
  File "/Users/Slaton/myvenv/flwr/lib/python3.9/site-packages/flwr/client/client.py", line 234, in maybe_call_fit
    return client.fit(fit_ins)
  File "/Users/Slaton/myvenv/flwr/lib/python3.9/site-packages/flwr/client/numpy_client.py", line 238, in _fit
    results = self.numpy_client.fit(parameters, ins.config)  # type: ignore
  File "/Users/Slaton/Documents/grenoble-code/fl-flower/project3-result/client.py", line 39, in fit
    self.set_parameters(parameters)
  File "/Users/Slaton/Documents/grenoble-code/fl-flower/project3-result/client.py", line 31, in set_parameters
    self.model.load_state_dict(state_dict, strict = False)
  File "/Users/Slaton/myvenv/flwr/lib/python3.9/site-packages/torch/nn/modules/module.py", line 2139, in load_state_dict
    load(self, state_dict)
  File "/Users/Slaton/myvenv/flwr/lib/python3.9/site-packages/torch/nn/modules/module.py", line 2127, in load
    load(child, child_state_dict, child_prefix)
  File "/Users/Slaton/myvenv/flwr/lib/python3.9/site-packages/torch/nn/modules/module.py", line 2127, in load
    load(child, child_state_dict, child_prefix)
  File "/Users/Slaton/myvenv/flwr/lib/python3.9/site-packages/torch/nn/modules/module.py", line 2127, in load
    load(child, child_state_dict, child_prefix)
  File "/Users/Slaton/myvenv/flwr/lib/python3.9/site-packages/torch/nn/modules/module.py", line 2121, in load
    module._load_from_state_dict(
  File "/Users/Slaton/myvenv/flwr/lib/python3.9/site-packages/torch/nn/modules/batchnorm.py", line 114, in _load_from_state_dict
    super()._load_from_state_dict(
  File "/Users/Slaton/myvenv/flwr/lib/python3.9/site-packages/torch/nn/modules/module.py", line 2015, in _load_from_state_dict
    input_param = input_param[0]
IndexError: index 0 is out of bounds for dimension 0 with size 0

The above exception was the direct cause of the following exception:

[36mray::DefaultActor.run()[39m (pid=57028, ip=127.0.0.1, actor_id=4c7ac826f305fef553fc9eee01000000, repr=<flwr.simulation.ray_transport.ray_actor.DefaultActor object at 0x111511a00>)
  File "/Users/Slaton/myvenv/flwr/lib/python3.9/site-packages/flwr/simulation/ray_transport/ray_actor.py", line 90, in run
    raise ClientException(str(message)) from ex
flwr.simulation.ray_transport.ray_actor.ClientException: 
>>>>>>>A ClientException occurred.('\n\tSomething went wrong when running your client run.\n\tClient 9 crashed when the DefaultActor was running its run.\n\tException triggered on the client side: Traceback (most recent call last):\n  File "/Users/Slaton/myvenv/flwr/lib/python3.9/site-packages/flwr/simulation/ray_transport/ray_actor.py", line 76, in run\n    job_results = job_fn(client)\n  File "/Users/Slaton/myvenv/flwr/lib/python3.9/site-packages/flwr/simulation/ray_transport/ray_client_proxy.py", line 207, in fit\n    return maybe_call_fit(\n  File "/Users/Slaton/myvenv/flwr/lib/python3.9/site-packages/flwr/client/client.py", line 234, in maybe_call_fit\n    return client.fit(fit_ins)\n  File "/Users/Slaton/myvenv/flwr/lib/python3.9/site-packages/flwr/client/numpy_client.py", line 238, in _fit\n    results = self.numpy_client.fit(parameters, ins.config)  # type: ignore\n  File "/Users/Slaton/Documents/grenoble-code/fl-flower/project3-result/client.py", line 39, in fit\n    self.set_parameters(parameters)\n  File "/Users/Slaton/Documents/grenoble-code/fl-flower/project3-result/client.py", line 31, in set_parameters\n    self.model.load_state_dict(state_dict, strict = False)\n  File "/Users/Slaton/myvenv/flwr/lib/python3.9/site-packages/torch/nn/modules/module.py", line 2139, in load_state_dict\n    load(self, state_dict)\n  File "/Users/Slaton/myvenv/flwr/lib/python3.9/site-packages/torch/nn/modules/module.py", line 2127, in load\n    load(child, child_state_dict, child_prefix)\n  File "/Users/Slaton/myvenv/flwr/lib/python3.9/site-packages/torch/nn/modules/module.py", line 2127, in load\n    load(child, child_state_dict, child_prefix)\n  File "/Users/Slaton/myvenv/flwr/lib/python3.9/site-packages/torch/nn/modules/module.py", line 2127, in load\n    load(child, child_state_dict, child_prefix)\n  File "/Users/Slaton/myvenv/flwr/lib/python3.9/site-packages/torch/nn/modules/module.py", line 2121, in load\n    module._load_from_state_dict(\n  File "/Users/Slaton/myvenv/flwr/lib/python3.9/site-packages/torch/nn/modules/batchnorm.py", line 114, in _load_from_state_dict\n    super()._load_from_state_dict(\n  File "/Users/Slaton/myvenv/flwr/lib/python3.9/site-packages/torch/nn/modules/module.py", line 2015, in _load_from_state_dict\n    input_param = input_param[0]\nIndexError: index 0 is out of bounds for dimension 0 with size 0\n',)

[2024-02-22 10:08:13,022][flwr][ERROR] - [36mray::DefaultActor.run()[39m (pid=57027, ip=127.0.0.1, actor_id=5bf67ed44f1870e964b6360401000000, repr=<flwr.simulation.ray_transport.ray_actor.DefaultActor object at 0x105d49a60>)
  File "/Users/Slaton/myvenv/flwr/lib/python3.9/site-packages/flwr/simulation/ray_transport/ray_client_proxy.py", line 207, in fit
    return maybe_call_fit(
  File "/Users/Slaton/myvenv/flwr/lib/python3.9/site-packages/flwr/client/client.py", line 234, in maybe_call_fit
    return client.fit(fit_ins)
  File "/Users/Slaton/myvenv/flwr/lib/python3.9/site-packages/flwr/client/numpy_client.py", line 238, in _fit
    results = self.numpy_client.fit(parameters, ins.config)  # type: ignore
  File "/Users/Slaton/Documents/grenoble-code/fl-flower/project3-result/client.py", line 39, in fit
    self.set_parameters(parameters)
  File "/Users/Slaton/Documents/grenoble-code/fl-flower/project3-result/client.py", line 31, in set_parameters
    self.model.load_state_dict(state_dict, strict = False)
  File "/Users/Slaton/myvenv/flwr/lib/python3.9/site-packages/torch/nn/modules/module.py", line 2139, in load_state_dict
    load(self, state_dict)
  File "/Users/Slaton/myvenv/flwr/lib/python3.9/site-packages/torch/nn/modules/module.py", line 2127, in load
    load(child, child_state_dict, child_prefix)
  File "/Users/Slaton/myvenv/flwr/lib/python3.9/site-packages/torch/nn/modules/module.py", line 2127, in load
    load(child, child_state_dict, child_prefix)
  File "/Users/Slaton/myvenv/flwr/lib/python3.9/site-packages/torch/nn/modules/module.py", line 2127, in load
    load(child, child_state_dict, child_prefix)
  File "/Users/Slaton/myvenv/flwr/lib/python3.9/site-packages/torch/nn/modules/module.py", line 2121, in load
    module._load_from_state_dict(
  File "/Users/Slaton/myvenv/flwr/lib/python3.9/site-packages/torch/nn/modules/batchnorm.py", line 114, in _load_from_state_dict
    super()._load_from_state_dict(
  File "/Users/Slaton/myvenv/flwr/lib/python3.9/site-packages/torch/nn/modules/module.py", line 2015, in _load_from_state_dict
    input_param = input_param[0]
IndexError: index 0 is out of bounds for dimension 0 with size 0

The above exception was the direct cause of the following exception:

[36mray::DefaultActor.run()[39m (pid=57027, ip=127.0.0.1, actor_id=5bf67ed44f1870e964b6360401000000, repr=<flwr.simulation.ray_transport.ray_actor.DefaultActor object at 0x105d49a60>)
  File "/Users/Slaton/myvenv/flwr/lib/python3.9/site-packages/flwr/simulation/ray_transport/ray_actor.py", line 90, in run
    raise ClientException(str(message)) from ex
flwr.simulation.ray_transport.ray_actor.ClientException: 
>>>>>>>A ClientException occurred.('\n\tSomething went wrong when running your client run.\n\tClient 0 crashed when the DefaultActor was running its run.\n\tException triggered on the client side: Traceback (most recent call last):\n  File "/Users/Slaton/myvenv/flwr/lib/python3.9/site-packages/flwr/simulation/ray_transport/ray_actor.py", line 76, in run\n    job_results = job_fn(client)\n  File "/Users/Slaton/myvenv/flwr/lib/python3.9/site-packages/flwr/simulation/ray_transport/ray_client_proxy.py", line 207, in fit\n    return maybe_call_fit(\n  File "/Users/Slaton/myvenv/flwr/lib/python3.9/site-packages/flwr/client/client.py", line 234, in maybe_call_fit\n    return client.fit(fit_ins)\n  File "/Users/Slaton/myvenv/flwr/lib/python3.9/site-packages/flwr/client/numpy_client.py", line 238, in _fit\n    results = self.numpy_client.fit(parameters, ins.config)  # type: ignore\n  File "/Users/Slaton/Documents/grenoble-code/fl-flower/project3-result/client.py", line 39, in fit\n    self.set_parameters(parameters)\n  File "/Users/Slaton/Documents/grenoble-code/fl-flower/project3-result/client.py", line 31, in set_parameters\n    self.model.load_state_dict(state_dict, strict = False)\n  File "/Users/Slaton/myvenv/flwr/lib/python3.9/site-packages/torch/nn/modules/module.py", line 2139, in load_state_dict\n    load(self, state_dict)\n  File "/Users/Slaton/myvenv/flwr/lib/python3.9/site-packages/torch/nn/modules/module.py", line 2127, in load\n    load(child, child_state_dict, child_prefix)\n  File "/Users/Slaton/myvenv/flwr/lib/python3.9/site-packages/torch/nn/modules/module.py", line 2127, in load\n    load(child, child_state_dict, child_prefix)\n  File "/Users/Slaton/myvenv/flwr/lib/python3.9/site-packages/torch/nn/modules/module.py", line 2127, in load\n    load(child, child_state_dict, child_prefix)\n  File "/Users/Slaton/myvenv/flwr/lib/python3.9/site-packages/torch/nn/modules/module.py", line 2121, in load\n    module._load_from_state_dict(\n  File "/Users/Slaton/myvenv/flwr/lib/python3.9/site-packages/torch/nn/modules/batchnorm.py", line 114, in _load_from_state_dict\n    super()._load_from_state_dict(\n  File "/Users/Slaton/myvenv/flwr/lib/python3.9/site-packages/torch/nn/modules/module.py", line 2015, in _load_from_state_dict\n    input_param = input_param[0]\nIndexError: index 0 is out of bounds for dimension 0 with size 0\n',)
[2024-02-22 10:08:13,023][flwr][ERROR] - [36mray::DefaultActor.run()[39m (pid=57028, ip=127.0.0.1, actor_id=4c7ac826f305fef553fc9eee01000000, repr=<flwr.simulation.ray_transport.ray_actor.DefaultActor object at 0x111511a00>)
  File "/Users/Slaton/myvenv/flwr/lib/python3.9/site-packages/flwr/simulation/ray_transport/ray_client_proxy.py", line 207, in fit
    return maybe_call_fit(
  File "/Users/Slaton/myvenv/flwr/lib/python3.9/site-packages/flwr/client/client.py", line 234, in maybe_call_fit
    return client.fit(fit_ins)
  File "/Users/Slaton/myvenv/flwr/lib/python3.9/site-packages/flwr/client/numpy_client.py", line 238, in _fit
    results = self.numpy_client.fit(parameters, ins.config)  # type: ignore
  File "/Users/Slaton/Documents/grenoble-code/fl-flower/project3-result/client.py", line 39, in fit
    self.set_parameters(parameters)
  File "/Users/Slaton/Documents/grenoble-code/fl-flower/project3-result/client.py", line 31, in set_parameters
    self.model.load_state_dict(state_dict, strict = False)
  File "/Users/Slaton/myvenv/flwr/lib/python3.9/site-packages/torch/nn/modules/module.py", line 2139, in load_state_dict
    load(self, state_dict)
  File "/Users/Slaton/myvenv/flwr/lib/python3.9/site-packages/torch/nn/modules/module.py", line 2127, in load
    load(child, child_state_dict, child_prefix)
  File "/Users/Slaton/myvenv/flwr/lib/python3.9/site-packages/torch/nn/modules/module.py", line 2127, in load
    load(child, child_state_dict, child_prefix)
  File "/Users/Slaton/myvenv/flwr/lib/python3.9/site-packages/torch/nn/modules/module.py", line 2127, in load
    load(child, child_state_dict, child_prefix)
  File "/Users/Slaton/myvenv/flwr/lib/python3.9/site-packages/torch/nn/modules/module.py", line 2121, in load
    module._load_from_state_dict(
  File "/Users/Slaton/myvenv/flwr/lib/python3.9/site-packages/torch/nn/modules/batchnorm.py", line 114, in _load_from_state_dict
    super()._load_from_state_dict(
  File "/Users/Slaton/myvenv/flwr/lib/python3.9/site-packages/torch/nn/modules/module.py", line 2015, in _load_from_state_dict
    input_param = input_param[0]
IndexError: index 0 is out of bounds for dimension 0 with size 0

The above exception was the direct cause of the following exception:

[36mray::DefaultActor.run()[39m (pid=57028, ip=127.0.0.1, actor_id=4c7ac826f305fef553fc9eee01000000, repr=<flwr.simulation.ray_transport.ray_actor.DefaultActor object at 0x111511a00>)
  File "/Users/Slaton/myvenv/flwr/lib/python3.9/site-packages/flwr/simulation/ray_transport/ray_actor.py", line 90, in run
    raise ClientException(str(message)) from ex
flwr.simulation.ray_transport.ray_actor.ClientException: 
>>>>>>>A ClientException occurred.('\n\tSomething went wrong when running your client run.\n\tClient 9 crashed when the DefaultActor was running its run.\n\tException triggered on the client side: Traceback (most recent call last):\n  File "/Users/Slaton/myvenv/flwr/lib/python3.9/site-packages/flwr/simulation/ray_transport/ray_actor.py", line 76, in run\n    job_results = job_fn(client)\n  File "/Users/Slaton/myvenv/flwr/lib/python3.9/site-packages/flwr/simulation/ray_transport/ray_client_proxy.py", line 207, in fit\n    return maybe_call_fit(\n  File "/Users/Slaton/myvenv/flwr/lib/python3.9/site-packages/flwr/client/client.py", line 234, in maybe_call_fit\n    return client.fit(fit_ins)\n  File "/Users/Slaton/myvenv/flwr/lib/python3.9/site-packages/flwr/client/numpy_client.py", line 238, in _fit\n    results = self.numpy_client.fit(parameters, ins.config)  # type: ignore\n  File "/Users/Slaton/Documents/grenoble-code/fl-flower/project3-result/client.py", line 39, in fit\n    self.set_parameters(parameters)\n  File "/Users/Slaton/Documents/grenoble-code/fl-flower/project3-result/client.py", line 31, in set_parameters\n    self.model.load_state_dict(state_dict, strict = False)\n  File "/Users/Slaton/myvenv/flwr/lib/python3.9/site-packages/torch/nn/modules/module.py", line 2139, in load_state_dict\n    load(self, state_dict)\n  File "/Users/Slaton/myvenv/flwr/lib/python3.9/site-packages/torch/nn/modules/module.py", line 2127, in load\n    load(child, child_state_dict, child_prefix)\n  File "/Users/Slaton/myvenv/flwr/lib/python3.9/site-packages/torch/nn/modules/module.py", line 2127, in load\n    load(child, child_state_dict, child_prefix)\n  File "/Users/Slaton/myvenv/flwr/lib/python3.9/site-packages/torch/nn/modules/module.py", line 2127, in load\n    load(child, child_state_dict, child_prefix)\n  File "/Users/Slaton/myvenv/flwr/lib/python3.9/site-packages/torch/nn/modules/module.py", line 2121, in load\n    module._load_from_state_dict(\n  File "/Users/Slaton/myvenv/flwr/lib/python3.9/site-packages/torch/nn/modules/batchnorm.py", line 114, in _load_from_state_dict\n    super()._load_from_state_dict(\n  File "/Users/Slaton/myvenv/flwr/lib/python3.9/site-packages/torch/nn/modules/module.py", line 2015, in _load_from_state_dict\n    input_param = input_param[0]\nIndexError: index 0 is out of bounds for dimension 0 with size 0\n',)
[2024-02-22 10:08:13,102][flwr][ERROR] - Traceback (most recent call last):
  File "/Users/Slaton/myvenv/flwr/lib/python3.9/site-packages/flwr/simulation/ray_transport/ray_client_proxy.py", line 151, in _submit_job
    res, updated_context = self.actor_pool.get_client_result(self.cid, timeout)
  File "/Users/Slaton/myvenv/flwr/lib/python3.9/site-packages/flwr/simulation/ray_transport/ray_actor.py", line 425, in get_client_result
    return self._fetch_future_result(cid)
  File "/Users/Slaton/myvenv/flwr/lib/python3.9/site-packages/flwr/simulation/ray_transport/ray_actor.py", line 306, in _fetch_future_result
    res_cid, res, updated_context = ray.get(
  File "/Users/Slaton/myvenv/flwr/lib/python3.9/site-packages/ray/_private/auto_init_hook.py", line 24, in auto_init_wrapper
    return fn(*args, **kwargs)
  File "/Users/Slaton/myvenv/flwr/lib/python3.9/site-packages/ray/_private/client_mode_hook.py", line 103, in wrapper
    return func(*args, **kwargs)
  File "/Users/Slaton/myvenv/flwr/lib/python3.9/site-packages/ray/_private/worker.py", line 2524, in get
    raise value.as_instanceof_cause()
ray.exceptions.RayTaskError(ClientException): [36mray::DefaultActor.run()[39m (pid=57027, ip=127.0.0.1, actor_id=5bf67ed44f1870e964b6360401000000, repr=<flwr.simulation.ray_transport.ray_actor.DefaultActor object at 0x105d49a60>)
  File "/Users/Slaton/myvenv/flwr/lib/python3.9/site-packages/flwr/simulation/ray_transport/ray_client_proxy.py", line 207, in fit
    return maybe_call_fit(
  File "/Users/Slaton/myvenv/flwr/lib/python3.9/site-packages/flwr/client/client.py", line 234, in maybe_call_fit
    return client.fit(fit_ins)
  File "/Users/Slaton/myvenv/flwr/lib/python3.9/site-packages/flwr/client/numpy_client.py", line 238, in _fit
    results = self.numpy_client.fit(parameters, ins.config)  # type: ignore
  File "/Users/Slaton/Documents/grenoble-code/fl-flower/project3-result/client.py", line 39, in fit
    self.set_parameters(parameters)
  File "/Users/Slaton/Documents/grenoble-code/fl-flower/project3-result/client.py", line 31, in set_parameters
    self.model.load_state_dict(state_dict, strict = False)
  File "/Users/Slaton/myvenv/flwr/lib/python3.9/site-packages/torch/nn/modules/module.py", line 2139, in load_state_dict
    load(self, state_dict)
  File "/Users/Slaton/myvenv/flwr/lib/python3.9/site-packages/torch/nn/modules/module.py", line 2127, in load
    load(child, child_state_dict, child_prefix)
  File "/Users/Slaton/myvenv/flwr/lib/python3.9/site-packages/torch/nn/modules/module.py", line 2127, in load
    load(child, child_state_dict, child_prefix)
  File "/Users/Slaton/myvenv/flwr/lib/python3.9/site-packages/torch/nn/modules/module.py", line 2127, in load
    load(child, child_state_dict, child_prefix)
  File "/Users/Slaton/myvenv/flwr/lib/python3.9/site-packages/torch/nn/modules/module.py", line 2121, in load
    module._load_from_state_dict(
  File "/Users/Slaton/myvenv/flwr/lib/python3.9/site-packages/torch/nn/modules/batchnorm.py", line 114, in _load_from_state_dict
    super()._load_from_state_dict(
  File "/Users/Slaton/myvenv/flwr/lib/python3.9/site-packages/torch/nn/modules/module.py", line 2015, in _load_from_state_dict
    input_param = input_param[0]
IndexError: index 0 is out of bounds for dimension 0 with size 0

The above exception was the direct cause of the following exception:

[36mray::DefaultActor.run()[39m (pid=57027, ip=127.0.0.1, actor_id=5bf67ed44f1870e964b6360401000000, repr=<flwr.simulation.ray_transport.ray_actor.DefaultActor object at 0x105d49a60>)
  File "/Users/Slaton/myvenv/flwr/lib/python3.9/site-packages/flwr/simulation/ray_transport/ray_actor.py", line 90, in run
    raise ClientException(str(message)) from ex
flwr.simulation.ray_transport.ray_actor.ClientException: 
>>>>>>>A ClientException occurred.('\n\tSomething went wrong when running your client run.\n\tClient 8 crashed when the DefaultActor was running its run.\n\tException triggered on the client side: Traceback (most recent call last):\n  File "/Users/Slaton/myvenv/flwr/lib/python3.9/site-packages/flwr/simulation/ray_transport/ray_actor.py", line 76, in run\n    job_results = job_fn(client)\n  File "/Users/Slaton/myvenv/flwr/lib/python3.9/site-packages/flwr/simulation/ray_transport/ray_client_proxy.py", line 207, in fit\n    return maybe_call_fit(\n  File "/Users/Slaton/myvenv/flwr/lib/python3.9/site-packages/flwr/client/client.py", line 234, in maybe_call_fit\n    return client.fit(fit_ins)\n  File "/Users/Slaton/myvenv/flwr/lib/python3.9/site-packages/flwr/client/numpy_client.py", line 238, in _fit\n    results = self.numpy_client.fit(parameters, ins.config)  # type: ignore\n  File "/Users/Slaton/Documents/grenoble-code/fl-flower/project3-result/client.py", line 39, in fit\n    self.set_parameters(parameters)\n  File "/Users/Slaton/Documents/grenoble-code/fl-flower/project3-result/client.py", line 31, in set_parameters\n    self.model.load_state_dict(state_dict, strict = False)\n  File "/Users/Slaton/myvenv/flwr/lib/python3.9/site-packages/torch/nn/modules/module.py", line 2139, in load_state_dict\n    load(self, state_dict)\n  File "/Users/Slaton/myvenv/flwr/lib/python3.9/site-packages/torch/nn/modules/module.py", line 2127, in load\n    load(child, child_state_dict, child_prefix)\n  File "/Users/Slaton/myvenv/flwr/lib/python3.9/site-packages/torch/nn/modules/module.py", line 2127, in load\n    load(child, child_state_dict, child_prefix)\n  File "/Users/Slaton/myvenv/flwr/lib/python3.9/site-packages/torch/nn/modules/module.py", line 2127, in load\n    load(child, child_state_dict, child_prefix)\n  File "/Users/Slaton/myvenv/flwr/lib/python3.9/site-packages/torch/nn/modules/module.py", line 2121, in load\n    module._load_from_state_dict(\n  File "/Users/Slaton/myvenv/flwr/lib/python3.9/site-packages/torch/nn/modules/batchnorm.py", line 114, in _load_from_state_dict\n    super()._load_from_state_dict(\n  File "/Users/Slaton/myvenv/flwr/lib/python3.9/site-packages/torch/nn/modules/module.py", line 2015, in _load_from_state_dict\n    input_param = input_param[0]\nIndexError: index 0 is out of bounds for dimension 0 with size 0\n',)

[2024-02-22 10:08:13,103][flwr][ERROR] - [36mray::DefaultActor.run()[39m (pid=57027, ip=127.0.0.1, actor_id=5bf67ed44f1870e964b6360401000000, repr=<flwr.simulation.ray_transport.ray_actor.DefaultActor object at 0x105d49a60>)
  File "/Users/Slaton/myvenv/flwr/lib/python3.9/site-packages/flwr/simulation/ray_transport/ray_client_proxy.py", line 207, in fit
    return maybe_call_fit(
  File "/Users/Slaton/myvenv/flwr/lib/python3.9/site-packages/flwr/client/client.py", line 234, in maybe_call_fit
    return client.fit(fit_ins)
  File "/Users/Slaton/myvenv/flwr/lib/python3.9/site-packages/flwr/client/numpy_client.py", line 238, in _fit
    results = self.numpy_client.fit(parameters, ins.config)  # type: ignore
  File "/Users/Slaton/Documents/grenoble-code/fl-flower/project3-result/client.py", line 39, in fit
    self.set_parameters(parameters)
  File "/Users/Slaton/Documents/grenoble-code/fl-flower/project3-result/client.py", line 31, in set_parameters
    self.model.load_state_dict(state_dict, strict = False)
  File "/Users/Slaton/myvenv/flwr/lib/python3.9/site-packages/torch/nn/modules/module.py", line 2139, in load_state_dict
    load(self, state_dict)
  File "/Users/Slaton/myvenv/flwr/lib/python3.9/site-packages/torch/nn/modules/module.py", line 2127, in load
    load(child, child_state_dict, child_prefix)
  File "/Users/Slaton/myvenv/flwr/lib/python3.9/site-packages/torch/nn/modules/module.py", line 2127, in load
    load(child, child_state_dict, child_prefix)
  File "/Users/Slaton/myvenv/flwr/lib/python3.9/site-packages/torch/nn/modules/module.py", line 2127, in load
    load(child, child_state_dict, child_prefix)
  File "/Users/Slaton/myvenv/flwr/lib/python3.9/site-packages/torch/nn/modules/module.py", line 2121, in load
    module._load_from_state_dict(
  File "/Users/Slaton/myvenv/flwr/lib/python3.9/site-packages/torch/nn/modules/batchnorm.py", line 114, in _load_from_state_dict
    super()._load_from_state_dict(
  File "/Users/Slaton/myvenv/flwr/lib/python3.9/site-packages/torch/nn/modules/module.py", line 2015, in _load_from_state_dict
    input_param = input_param[0]
IndexError: index 0 is out of bounds for dimension 0 with size 0

The above exception was the direct cause of the following exception:

[36mray::DefaultActor.run()[39m (pid=57027, ip=127.0.0.1, actor_id=5bf67ed44f1870e964b6360401000000, repr=<flwr.simulation.ray_transport.ray_actor.DefaultActor object at 0x105d49a60>)
  File "/Users/Slaton/myvenv/flwr/lib/python3.9/site-packages/flwr/simulation/ray_transport/ray_actor.py", line 90, in run
    raise ClientException(str(message)) from ex
flwr.simulation.ray_transport.ray_actor.ClientException: 
>>>>>>>A ClientException occurred.('\n\tSomething went wrong when running your client run.\n\tClient 8 crashed when the DefaultActor was running its run.\n\tException triggered on the client side: Traceback (most recent call last):\n  File "/Users/Slaton/myvenv/flwr/lib/python3.9/site-packages/flwr/simulation/ray_transport/ray_actor.py", line 76, in run\n    job_results = job_fn(client)\n  File "/Users/Slaton/myvenv/flwr/lib/python3.9/site-packages/flwr/simulation/ray_transport/ray_client_proxy.py", line 207, in fit\n    return maybe_call_fit(\n  File "/Users/Slaton/myvenv/flwr/lib/python3.9/site-packages/flwr/client/client.py", line 234, in maybe_call_fit\n    return client.fit(fit_ins)\n  File "/Users/Slaton/myvenv/flwr/lib/python3.9/site-packages/flwr/client/numpy_client.py", line 238, in _fit\n    results = self.numpy_client.fit(parameters, ins.config)  # type: ignore\n  File "/Users/Slaton/Documents/grenoble-code/fl-flower/project3-result/client.py", line 39, in fit\n    self.set_parameters(parameters)\n  File "/Users/Slaton/Documents/grenoble-code/fl-flower/project3-result/client.py", line 31, in set_parameters\n    self.model.load_state_dict(state_dict, strict = False)\n  File "/Users/Slaton/myvenv/flwr/lib/python3.9/site-packages/torch/nn/modules/module.py", line 2139, in load_state_dict\n    load(self, state_dict)\n  File "/Users/Slaton/myvenv/flwr/lib/python3.9/site-packages/torch/nn/modules/module.py", line 2127, in load\n    load(child, child_state_dict, child_prefix)\n  File "/Users/Slaton/myvenv/flwr/lib/python3.9/site-packages/torch/nn/modules/module.py", line 2127, in load\n    load(child, child_state_dict, child_prefix)\n  File "/Users/Slaton/myvenv/flwr/lib/python3.9/site-packages/torch/nn/modules/module.py", line 2127, in load\n    load(child, child_state_dict, child_prefix)\n  File "/Users/Slaton/myvenv/flwr/lib/python3.9/site-packages/torch/nn/modules/module.py", line 2121, in load\n    module._load_from_state_dict(\n  File "/Users/Slaton/myvenv/flwr/lib/python3.9/site-packages/torch/nn/modules/batchnorm.py", line 114, in _load_from_state_dict\n    super()._load_from_state_dict(\n  File "/Users/Slaton/myvenv/flwr/lib/python3.9/site-packages/torch/nn/modules/module.py", line 2015, in _load_from_state_dict\n    input_param = input_param[0]\nIndexError: index 0 is out of bounds for dimension 0 with size 0\n',)
[2024-02-22 10:08:13,104][flwr][DEBUG] - fit_round 1 received 0 results and 10 failures
